Workbook

Sheet Results_Parallel
A1: Ordering | B1: Key | C1: Filename | D1: Attempt | E1: Success | F1: Time Gen | G1: Time Ver | H1: Time API Call | I1: Success Merged Original | J1: Success Raw | K1: Success Postprocessed | L1: C | M1: Attempts to Success | N1: pass@2 | O1: pass@3 | P1: LOC llm | Q1: LOC man | R1: Helpers + lemmas
A2: 1 | B2: =C2&"-"&D2 -> BinarySearch.dfy-1 | C2: BinarySearch.dfy | D2: 1 | E2: =MAX(IFERROR(VLOOKUP(B2,'Results_ClaudeOpus4.5'!B:E,4,0),0),IFERROR(VLOOKUP(B2,'Results_GPT5.2Low'!B:E,4,0),0)) -> 1 | F2: =MAX('Results_ClaudeOpus4.5'!F2,'Results_GPT5.2Low'!F2) -> 13.3909 | G2: =MAX('Results_ClaudeOpus4.5'!G2,'Results_GPT5.2Low'!G2) -> 2.2487 | H2: =MAX(IFERROR(VLOOKUP(B2,'Results_ClaudeOpus4.5'!B:H,7,0),0),IFERROR(VLOOKUP(B2,'Results_GPT5.2Low'!B:H,7,0),0)) -> 13.3728 | I2: 1 | J2: 1 | K2: 1 | L2: =COUNTIFS(C:C,C2,E:E,1) -> 3 | M2: =_xlfn.MINIFS(D:D,C:C,C2,E:E,1) -> 1 | N2: =CHOOSE(L2+1,0,2/3,1,1) -> 1 | O2: =IF(L2>0,1,0) -> 1 | P2: =MIN(IF(IFERROR(VLOOKUP(B2,'Results_ClaudeOpus4.5'!B:E,4,0),0)=1,VLOOKUP(B2,'Results_ClaudeOpus4.5'!B:P,15,0),1000),IF(IFERROR(VLOOKUP(B2,'Results_GPT5.2Low'!B:E,4,0),0)=1,VLOOKUP(B2,'Results_GPT5.2Low'!B:P,15,0),1000)) -> 44 | Q2: =VLOOKUP(C2,Locs!A:C,3,0) -> 38 | R2: =VLOOKUP(C2,Locs!A:F,6,0) -> 0
A3: 2 | B3: =C3&"-"&D3 -> BinarySearch.dfy-2 | C3: BinarySearch.dfy | D3: 2 | E3: =MAX(IFERROR(VLOOKUP(B3,'Results_ClaudeOpus4.5'!B:E,4,0),0),IFERROR(VLOOKUP(B3,'Results_GPT5.2Low'!B:E,4,0),0)) -> 1 | F3: =MAX('Results_ClaudeOpus4.5'!F3,'Results_GPT5.2Low'!F3) -> 8.5129 | G3: =MAX('Results_ClaudeOpus4.5'!G3,'Results_GPT5.2Low'!G3) -> 2.2863 | H3: =MAX(IFERROR(VLOOKUP(B3,'Results_ClaudeOpus4.5'!B:H,7,0),0),IFERROR(VLOOKUP(B3,'Results_GPT5.2Low'!B:H,7,0),0)) -> 8.5107 | I3: 1 | J3: 1 | K3: 1 | L3: =COUNTIFS(C:C,C3,E:E,1) -> 3 | M3: =_xlfn.MINIFS(D:D,C:C,C3,E:E,1) -> 1 | N3: =CHOOSE(L3+1,0,2/3,1,1) -> 1 | O3: =IF(L3>0,1,0) -> 1 | P3: =MIN(IF(IFERROR(VLOOKUP(B3,'Results_ClaudeOpus4.5'!B:E,4,0),0)=1,VLOOKUP(B3,'Results_ClaudeOpus4.5'!B:P,15,0),1000),IF(IFERROR(VLOOKUP(B3,'Results_GPT5.2Low'!B:E,4,0),0)=1,VLOOKUP(B3,'Results_GPT5.2Low'!B:P,15,0),1000)) -> 43 | Q3: =VLOOKUP(C3,Locs!A:C,3,0) -> 38 | R3: =VLOOKUP(C3,Locs!A:F,6,0) -> 0
A4: 3 | B4: =C4&"-"&D4 -> BinarySearch.dfy-3 | C4: BinarySearch.dfy | D4: 3 | E4: =MAX(IFERROR(VLOOKUP(B4,'Results_ClaudeOpus4.5'!B:E,4,0),0),IFERROR(VLOOKUP(B4,'Results_GPT5.2Low'!B:E,4,0),0)) -> 1 | F4: =MAX('Results_ClaudeOpus4.5'!F4,'Results_GPT5.2Low'!F4) -> 7.4215 | G4: =MAX('Results_ClaudeOpus4.5'!G4,'Results_GPT5.2Low'!G4) -> 1.6851 | H4: =MAX(IFERROR(VLOOKUP(B4,'Results_ClaudeOpus4.5'!B:H,7,0),0),IFERROR(VLOOKUP(B4,'Results_GPT5.2Low'!B:H,7,0),0)) -> 7.4191 | I4: 1 | J4: 1 | K4: 1 | L4: =COUNTIFS(C:C,C4,E:E,1) -> 3 | M4: =_xlfn.MINIFS(D:D,C:C,C4,E:E,1) -> 1 | N4: =CHOOSE(L4+1,0,2/3,1,1) -> 1 | O4: =IF(L4>0,1,0) -> 1 | P4: =MIN(IF(IFERROR(VLOOKUP(B4,'Results_ClaudeOpus4.5'!B:E,4,0),0)=1,VLOOKUP(B4,'Results_ClaudeOpus4.5'!B:P,15,0),1000),IF(IFERROR(VLOOKUP(B4,'Results_GPT5.2Low'!B:E,4,0),0)=1,VLOOKUP(B4,'Results_GPT5.2Low'!B:P,15,0),1000)) -> 46 | Q4: =VLOOKUP(C4,Locs!A:C,3,0) -> 38 | R4: =VLOOKUP(C4,Locs!A:F,6,0) -> 0
A5: 4 | B5: =C5&"-"&D5 -> BubbleSort.dfy-1 | C5: BubbleSort.dfy | D5: 1 | E5: =MAX(IFERROR(VLOOKUP(B5,'Results_ClaudeOpus4.5'!B:E,4,0),0),IFERROR(VLOOKUP(B5,'Results_GPT5.2Low'!B:E,4,0),0)) -> 0 | F5: =MAX('Results_ClaudeOpus4.5'!F5,'Results_GPT5.2Low'!F5) -> 96.9746 | G5: =MAX('Results_ClaudeOpus4.5'!G5,'Results_GPT5.2Low'!G5) -> 4.4049 | H5: =MAX(IFERROR(VLOOKUP(B5,'Results_ClaudeOpus4.5'!B:H,7,0),0),IFERROR(VLOOKUP(B5,'Results_GPT5.2Low'!B:H,7,0),0)) -> 96.9528 | I5: -1 | J5: 0 | K5: 0 | L5: =COUNTIFS(C:C,C5,E:E,1) -> 0 | M5: =_xlfn.MINIFS(D:D,C:C,C5,E:E,1) -> 0 | N5: =CHOOSE(L5+1,0,2/3,1,1) -> 0 | O5: =IF(L5>0,1,0) -> 0 | P5: =MIN(IF(IFERROR(VLOOKUP(B5,'Results_ClaudeOpus4.5'!B:E,4,0),0)=1,VLOOKUP(B5,'Results_ClaudeOpus4.5'!B:P,15,0),1000),IF(IFERROR(VLOOKUP(B5,'Results_GPT5.2Low'!B:E,4,0),0)=1,VLOOKUP(B5,'Results_GPT5.2Low'!B:P,15,0),1000)) -> 1000 | Q5: =VLOOKUP(C5,Locs!A:C,3,0) -> 44 | R5: =VLOOKUP(C5,Locs!A:F,6,0) -> 1
A6: 5 | B6: =C6&"-"&D6 -> BubbleSort.dfy-2 | C6: BubbleSort.dfy | D6: 2 | E6: =MAX(IFERROR(VLOOKUP(B6,'Results_ClaudeOpus4.5'!B:E,4,0),0),IFERROR(VLOOKUP(B6,'Results_GPT5.2Low'!B:E,4,0),0)) -> 0 | F6: =MAX('Results_ClaudeOpus4.5'!F6,'Results_GPT5.2Low'!F6) -> 101.0192 | G6: =MAX('Results_ClaudeOpus4.5'!G6,'Results_GPT5.2Low'!G6) -> 2.4527 | H6: =MAX(IFERROR(VLOOKUP(B6,'Results_ClaudeOpus4.5'!B:H,7,0),0),IFERROR(VLOOKUP(B6,'Results_GPT5.2Low'!B:H,7,0),0)) -> 101.0111 | I6: -1 | J6: 0 | K6: 0 | L6: =COUNTIFS(C:C,C6,E:E,1) -> 0 | M6: =_xlfn.MINIFS(D:D,C:C,C6,E:E,1) -> 0 | N6: =CHOOSE(L6+1,0,2/3,1,1) -> 0 | O6: =IF(L6>0,1,0) -> 0 | P6: =MIN(IF(IFERROR(VLOOKUP(B6,'Results_ClaudeOpus4.5'!B:E,4,0),0)=1,VLOOKUP(B6,'Results_ClaudeOpus4.5'!B:P,15,0),1000),IF(IFERROR(VLOOKUP(B6,'Results_GPT5.2Low'!B:E,4,0),0)=1,VLOOKUP(B6,'Results_GPT5.2Low'!B:P,15,0),1000)) -> 1000 | Q6: =VLOOKUP(C6,Locs!A:C,3,0) -> 44 | R6: =VLOOKUP(C6,Locs!A:F,6,0) -> 1
A7: 6 | B7: =C7&"-"&D7 -> BubbleSort.dfy-3 | C7: BubbleSort.dfy | D7: 3 | E7: =MAX(IFERROR(VLOOKUP(B7,'Results_ClaudeOpus4.5'!B:E,4,0),0),IFERROR(VLOOKUP(B7,'Results_GPT5.2Low'!B:E,4,0),0)) -> 0 | F7: =MAX('Results_ClaudeOpus4.5'!F7,'Results_GPT5.2Low'!F7) -> 95.0839 | G7: =MAX('Results_ClaudeOpus4.5'!G7,'Results_GPT5.2Low'!G7) -> 2.7174 | H7: =MAX(IFERROR(VLOOKUP(B7,'Results_ClaudeOpus4.5'!B:H,7,0),0),IFERROR(VLOOKUP(B7,'Results_GPT5.2Low'!B:H,7,0),0)) -> 95.0817 | I7: -1 | J7: 0 | K7: 0 | L7: =COUNTIFS(C:C,C7,E:E,1) -> 0 | M7: =_xlfn.MINIFS(D:D,C:C,C7,E:E,1) -> 0 | N7: =CHOOSE(L7+1,0,2/3,1,1) -> 0 | O7: =IF(L7>0,1,0) -> 0 | P7: =MIN(IF(IFERROR(VLOOKUP(B7,'Results_ClaudeOpus4.5'!B:E,4,0),0)=1,VLOOKUP(B7,'Results_ClaudeOpus4.5'!B:P,15,0),1000),IF(IFERROR(VLOOKUP(B7,'Results_GPT5.2Low'!B:E,4,0),0)=1,VLOOKUP(B7,'Results_GPT5.2Low'!B:P,15,0),1000)) -> 1000 | Q7: =VLOOKUP(C7,Locs!A:C,3,0) -> 44 | R7: =VLOOKUP(C7,Locs!A:F,6,0) -> 1
A8: 7 | B8: =C8&"-"&D8 -> BubbleSort.dfy-4 | C8: BubbleSort.dfy | D8: 4 | E8: =MAX(IFERROR(VLOOKUP(B8,'Results_ClaudeOpus4.5'!B:E,4,0),0),IFERROR(VLOOKUP(B8,'Results_GPT5.2Low'!B:E,4,0),0)) -> 0 | F8: =MAX('Results_ClaudeOpus4.5'!F8,'Results_GPT5.2Low'!F8) -> 207.4272 | G8: =MAX('Results_ClaudeOpus4.5'!G8,'Results_GPT5.2Low'!G8) -> 4.2118 | H8: =MAX(IFERROR(VLOOKUP(B8,'Results_ClaudeOpus4.5'!B:H,7,0),0),IFERROR(VLOOKUP(B8,'Results_GPT5.2Low'!B:H,7,0),0)) -> 207.4196 | I8: 1 | J8: 1 | K8: 1 | L8: =COUNTIFS(C:C,C8,E:E,1) -> 0 | M8: =_xlfn.MINIFS(D:D,C:C,C8,E:E,1) -> 0 | N8: =CHOOSE(L8+1,0,2/3,1,1) -> 0 | O8: =IF(L8>0,1,0) -> 0 | P8: =MIN(IF(IFERROR(VLOOKUP(B8,'Results_ClaudeOpus4.5'!B:E,4,0),0)=1,VLOOKUP(B8,'Results_ClaudeOpus4.5'!B:P,15,0),1000),IF(IFERROR(VLOOKUP(B8,'Results_GPT5.2Low'!B:E,4,0),0)=1,VLOOKUP(B8,'Results_GPT5.2Low'!B:P,15,0),1000)) -> 1000 | Q8: =VLOOKUP(C8,Locs!A:C,3,0) -> 44 | R8: =VLOOKUP(C8,Locs!A:F,6,0) -> 1
A9: 8 | B9: =C9&"-"&D9 -> BubbleSort.dfy-5 | C9: BubbleSort.dfy | D9: 5 | E9: =MAX(IFERROR(VLOOKUP(B9,'Results_ClaudeOpus4.5'!B:E,4,0),0),IFERROR(VLOOKUP(B9,'Results_GPT5.2Low'!B:E,4,0),0)) -> 0 | F9: =MAX('Results_ClaudeOpus4.5'!F9,'Results_GPT5.2Low'!F9) -> 117.9149 | G9: =MAX('Results_ClaudeOpus4.5'!G9,'Results_GPT5.2Low'!G9) -> 2.4522 | H9: =MAX(IFERROR(VLOOKUP(B9,'Results_ClaudeOpus4.5'!B:H,7,0),0),IFERROR(VLOOKUP(B9,'Results_GPT5.2Low'!B:H,7,0),0)) -> 117.9127 | I9: 1 | J9: 1 | K9: 1 | L9: =COUNTIFS(C:C,C9,E:E,1) -> 0 | M9: =_xlfn.MINIFS(D:D,C:C,C9,E:E,1) -> 0 | N9: =CHOOSE(L9+1,0,2/3,1,1) -> 0 | O9: =IF(L9>0,1,0) -> 0 | P9: =MIN(IF(IFERROR(VLOOKUP(B9,'Results_ClaudeOpus4.5'!B:E,4,0),0)=1,VLOOKUP(B9,'Results_ClaudeOpus4.5'!B:P,15,0),1000),IF(IFERROR(VLOOKUP(B9,'Results_GPT5.2Low'!B:E,4,0),0)=1,VLOOKUP(B9,'Results_GPT5.2Low'!B:P,15,0),1000)) -> 1000 | Q9: =VLOOKUP(C9,Locs!A:C,3,0) -> 44 | R9: =VLOOKUP(C9,Locs!A:F,6,0) -> 1
A10: 9 | B10: =C10&"-"&D10 -> Catalan.dfy-1 | C10: Catalan.dfy | D10: 1 | E10: =MAX(IFERROR(VLOOKUP(B10,'Results_ClaudeOpus4.5'!B:E,4,0),0),IFERROR(VLOOKUP(B10,'Results_GPT5.2Low'!B:E,4,0),0)) -> 1 | F10: =MAX('Results_ClaudeOpus4.5'!F10,'Results_GPT5.2Low'!F10) -> 30.7428 | G10: =MAX('Results_ClaudeOpus4.5'!G10,'Results_GPT5.2Low'!G10) -> 2.2412 | H10: =MAX(IFERROR(VLOOKUP(B10,'Results_ClaudeOpus4.5'!B:H,7,0),0),IFERROR(VLOOKUP(B10,'Results_GPT5.2Low'!B:H,7,0),0)) -> 30.7227 | I10: 1 | J10: 1 | K10: 1 | L10: =COUNTIFS(C:C,C10,E:E,1) -> 3 | M10: =_xlfn.MINIFS(D:D,C:C,C10,E:E,1) -> 1 | N10: =CHOOSE(L10+1,0,2/3,1,1) -> 1 | O10: =IF(L10>0,1,0) -> 1 | P10: =MIN(IF(IFERROR(VLOOKUP(B10,'Results_ClaudeOpus4.5'!B:E,4,0),0)=1,VLOOKUP(B10,'Results_ClaudeOpus4.5'!B:P,15,0),1000),IF(IFERROR(VLOOKUP(B10,'Results_GPT5.2Low'!B:E,4,0),0)=1,VLOOKUP(B10,'Results_GPT5.2Low'!B:P,15,0),1000)) -> 30 | Q10: =VLOOKUP(C10,Locs!A:C,3,0) -> 28 | R10: =VLOOKUP(C10,Locs!A:F,6,0) -> 0
A11: 10 | B11: =C11&"-"&D11 -> Catalan.dfy-2 | C11: Catalan.dfy | D11: 2 | E11: =MAX(IFERROR(VLOOKUP(B11,'Results_ClaudeOpus4.5'!B:E,4,0),0),IFERROR(VLOOKUP(B11,'Results_GPT5.2Low'!B:E,4,0),0)) -> 1 | F11: =MAX('Results_ClaudeOpus4.5'!F11,'Results_GPT5.2Low'!F11) -> 32.4286 | G11: =MAX('Results_ClaudeOpus4.5'!G11,'Results_GPT5.2Low'!G11) -> 1.3656 | H11: =MAX(IFERROR(VLOOKUP(B11,'Results_ClaudeOpus4.5'!B:H,7,0),0),IFERROR(VLOOKUP(B11,'Results_GPT5.2Low'!B:H,7,0),0)) -> 32.4262 | I11: -1 | J11: 0 | K11: 0 | L11: =COUNTIFS(C:C,C11,E:E,1) -> 3 | M11: =_xlfn.MINIFS(D:D,C:C,C11,E:E,1) -> 1 | N11: =CHOOSE(L11+1,0,2/3,1,1) -> 1 | O11: =IF(L11>0,1,0) -> 1 | P11: =MIN(IF(IFERROR(VLOOKUP(B11,'Results_ClaudeOpus4.5'!B:E,4,0),0)=1,VLOOKUP(B11,'Results_ClaudeOpus4.5'!B:P,15,0),1000),IF(IFERROR(VLOOKUP(B11,'Results_GPT5.2Low'!B:E,4,0),0)=1,VLOOKUP(B11,'Results_GPT5.2Low'!B:P,15,0),1000)) -> 30 | Q11: =VLOOKUP(C11,Locs!A:C,3,0) -> 28 | R11: =VLOOKUP(C11,Locs!A:F,6,0) -> 0
A12: 11 | B12: =C12&"-"&D12 -> Catalan.dfy-3 | C12: Catalan.dfy | D12: 3 | E12: =MAX(IFERROR(VLOOKUP(B12,'Results_ClaudeOpus4.5'!B:E,4,0),0),IFERROR(VLOOKUP(B12,'Results_GPT5.2Low'!B:E,4,0),0)) -> 1 | F12: =MAX('Results_ClaudeOpus4.5'!F12,'Results_GPT5.2Low'!F12) -> 14.5678 | G12: =MAX('Results_ClaudeOpus4.5'!G12,'Results_GPT5.2Low'!G12) -> 61.2425 | H12: =MAX(IFERROR(VLOOKUP(B12,'Results_ClaudeOpus4.5'!B:H,7,0),0),IFERROR(VLOOKUP(B12,'Results_GPT5.2Low'!B:H,7,0),0)) -> 14.5579 | I12: -1 | J12: 0 | K12: 0 | L12: =COUNTIFS(C:C,C12,E:E,1) -> 3 | M12: =_xlfn.MINIFS(D:D,C:C,C12,E:E,1) -> 1 | N12: =CHOOSE(L12+1,0,2/3,1,1) -> 1 | O12: =IF(L12>0,1,0) -> 1 | P12: =MIN(IF(IFERROR(VLOOKUP(B12,'Results_ClaudeOpus4.5'!B:E,4,0),0)=1,VLOOKUP(B12,'Results_ClaudeOpus4.5'!B:P,15,0),1000),IF(IFERROR(VLOOKUP(B12,'Results_GPT5.2Low'!B:E,4,0),0)=1,VLOOKUP(B12,'Results_GPT5.2Low'!B:P,15,0),1000)) -> 30 | Q12: =VLOOKUP(C12,Locs!A:C,3,0) -> 28 | R12: =VLOOKUP(C12,Locs!A:F,6,0) -> 0
A13: 12 | B13: =C13&"-"&D13 -> CombNK.dfy-1 | C13: CombNK.dfy | D13: 1 | E13: =MAX(IFERROR(VLOOKUP(B13,'Results_ClaudeOpus4.5'!B:E,4,0),0),IFERROR(VLOOKUP(B13,'Results_GPT5.2Low'!B:E,4,0),0)) -> 1 | F13: =MAX('Results_ClaudeOpus4.5'!F13,'Results_GPT5.2Low'!F13) -> 26.414 | G13: =MAX('Results_ClaudeOpus4.5'!G13,'Results_GPT5.2Low'!G13) -> 2.2477 | H13: =MAX(IFERROR(VLOOKUP(B13,'Results_ClaudeOpus4.5'!B:H,7,0),0),IFERROR(VLOOKUP(B13,'Results_GPT5.2Low'!B:H,7,0),0)) -> 26.3899 | I13: -1 | J13: 0 | K13: 0 | L13: =COUNTIFS(C:C,C13,E:E,1) -> 2 | M13: =_xlfn.MINIFS(D:D,C:C,C13,E:E,1) -> 1 | N13: =CHOOSE(L13+1,0,2/3,1,1) -> 1 | O13: =IF(L13>0,1,0) -> 1 | P13: =MIN(IF(IFERROR(VLOOKUP(B13,'Results_ClaudeOpus4.5'!B:E,4,0),0)=1,VLOOKUP(B13,'Results_ClaudeOpus4.5'!B:P,15,0),1000),IF(IFERROR(VLOOKUP(B13,'Results_GPT5.2Low'!B:E,4,0),0)=1,VLOOKUP(B13,'Results_GPT5.2Low'!B:P,15,0),1000)) -> 48 | Q13: =VLOOKUP(C13,Locs!A:C,3,0) -> 38 | R13: =VLOOKUP(C13,Locs!A:F,6,0) -> 0
... A331: 330 | B331: =C331&"-"&D331 -> task_id_629.dfy-3 | C331: task_id_629.dfy | D331: 3 | E331: =MAX(IFERROR(VLOOKUP(B331,'Results_ClaudeOpus4.5'!B:E,4,0),0),IFERROR(VLOOKUP(B331,'Results_GPT5.2Low'!B:E,4,0),0)) -> 1 | F331: =MAX('Results_ClaudeOpus4.5'!F331,'Results_GPT5.2Low'!F331) -> 8.2612 | G331: =MAX('Results_ClaudeOpus4.5'!G331,'Results_GPT5.2Low'!G331) -> 2.4806 | H331: =MAX(IFERROR(VLOOKUP(B331,'Results_ClaudeOpus4.5'!B:H,7,0),0),IFERROR(VLOOKUP(B331,'Results_GPT5.2Low'!B:H,7,0),0)) -> 15.5691 | I331: 1 | J331: 0 | K331: 0 | L331: =COUNTIFS(C:C,C331,E:E,1) -> 3 | M331: =_xlfn.MINIFS(D:D,C:C,C331,E:E,1) -> 1 | N331: =CHOOSE(L331+1,0,2/3,1,1) -> 1 | O331: =IF(L331>0,1,0) -> 1 | P331: =MIN(IF(IFERROR(VLOOKUP(B331,'Results_ClaudeOpus4.5'!B:E,4,0),0)=1,VLOOKUP(B331,'Results_ClaudeOpus4.5'!B:P,15,0),1000),IF(IFERROR(VLOOKUP(B331,'Results_GPT5.2Low'!B:E,4,0),0)=1,VLOOKUP(B331,'Results_GPT5.2Low'!B:P,15,0),1000)) -> 45 | Q331: =VLOOKUP(C331,Locs!A:C,3,0) -> 49 | R331: =VLOOKUP(C331,Locs!A:F,6,0) -> 2
B332: =C332&"-"&D332 -> task_id_632.dfy-1 | C332: task_id_632.dfy | D332: 1 | E332: =MAX(IFERROR(VLOOKUP(B332,'Results_ClaudeOpus4.5'!B:E,4,0),0),IFERROR(VLOOKUP(B332,'Results_GPT5.2Low'!B:E,4,0),0)) -> 0 | F332: =MAX('Results_ClaudeOpus4.5'!F332,'Results_GPT5.2Low'!F332) -> 22.3121 | G332: =MAX('Results_ClaudeOpus4.5'!G332,'Results_GPT5.2Low'!G332) -> 2.6992 | H332: =MAX(IFERROR(VLOOKUP(B332,'Results_ClaudeOpus4.5'!B:H,7,0),0),IFERROR(VLOOKUP(B332,'Results_GPT5.2Low'!B:H,7,0),0)) -> 26.1676 | I332: 1 | J332: 0 | K332: 0 | L332: =COUNTIFS(C:C,C332,E:E,1) -> 0 | M332: =_xlfn.MINIFS(D:D,C:C,C332,E:E,1) -> 0 | N332: =CHOOSE(L332+1,0,2/3,1,1) -> 0 | O332: =IF(L332>0,1,0) -> 0 | P332: =MIN(IF(IFERROR(VLOOKUP(B332,'Results_ClaudeOpus4.5'!B:E,4,0),0)=1,VLOOKUP(B332,'Results_ClaudeOpus4.5'!B:P,15,0),1000),IF(IFERROR(VLOOKUP(B332,'Results_GPT5.2Low'!B:E,4,0),0)=1,VLOOKUP(B332,'Results_GPT5.2Low'!B:P,15,0),1000)) -> 1000 | Q332: =VLOOKUP(C332,Locs!A:C,3,0) -> 48 | R332: =VLOOKUP(C332,Locs!A:F,6,0) -> 2
B333: =C333&"-"&D333 -> task_id_632.dfy-2 | C333: task_id_632.dfy | D333: 2 | E333: =MAX(IFERROR(VLOOKUP(B333,'Results_ClaudeOpus4.5'!B:E,4,0),0),IFERROR(VLOOKUP(B333,'Results_GPT5.2Low'!B:E,4,0),0)) -> 0 | F333: =MAX('Results_ClaudeOpus4.5'!F333,'Results_GPT5.2Low'!F333) -> 11.2195 | G333: =MAX('Results_ClaudeOpus4.5'!G333,'Results_GPT5.2Low'!G333) -> 2.8043 | H333: =MAX(IFERROR(VLOOKUP(B333,'Results_ClaudeOpus4.5'!B:H,7,0),0),IFERROR(VLOOKUP(B333,'Results_GPT5.2Low'!B:H,7,0),0)) -> 56.9745 | I333: 1 | J333: 0 | K333: 0 | L333: =COUNTIFS(C:C,C333,E:E,1) -> 0 | M333: =_xlfn.MINIFS(D:D,C:C,C333,E:E,1) -> 0 | N333: =CHOOSE(L333+1,0,2/3,1,1) -> 0 | O333: =IF(L333>0,1,0) -> 0 | P333: =MIN(IF(IFERROR(VLOOKUP(B333,'Results_ClaudeOpus4.5'!B:E,4,0),0)=1,VLOOKUP(B333,'Results_ClaudeOpus4.5'!B:P,15,0),1000),IF(IFERROR(VLOOKUP(B333,'Results_GPT5.2Low'!B:E,4,0),0)=1,VLOOKUP(B333,'Results_GPT5.2Low'!B:P,15,0),1000)) -> 1000 | Q333: =VLOOKUP(C333,Locs!A:C,3,0) -> 48 | R333: =VLOOKUP(C333,Locs!A:F,6,0) -> 2
B334: =C334&"-"&D334 -> task_id_632.dfy-3 | C334: task_id_632.dfy | D334: 3 | E334: =MAX(IFERROR(VLOOKUP(B334,'Results_ClaudeOpus4.5'!B:E,4,0),0),IFERROR(VLOOKUP(B334,'Results_GPT5.2Low'!B:E,4,0),0)) -> 0 | F334: =MAX('Results_ClaudeOpus4.5'!F334,'Results_GPT5.2Low'!F334) -> 11.404 | G334: =MAX('Results_ClaudeOpus4.5'!G334,'Results_GPT5.2Low'!G334) -> 2.6997 | H334: =MAX(IFERROR(VLOOKUP(B334,'Results_ClaudeOpus4.5'!B:H,7,0),0),IFERROR(VLOOKUP(B334,'Results_GPT5.2Low'!B:H,7,0),0)) -> 30.4111 | I334: 1 | J334: 0 | K334: 0 | L334: =COUNTIFS(C:C,C334,E:E,1) -> 0 | M334: =_xlfn.MINIFS(D:D,C:C,C334,E:E,1) -> 0 | N334: =CHOOSE(L334+1,0,2/3,1,1) -> 0 | O334: =IF(L334>0,1,0) -> 0 | P334: =MIN(IF(IFERROR(VLOOKUP(B334,'Results_ClaudeOpus4.5'!B:E,4,0),0)=1,VLOOKUP(B334,'Results_ClaudeOpus4.5'!B:P,15,0),1000),IF(IFERROR(VLOOKUP(B334,'Results_GPT5.2Low'!B:E,4,0),0)=1,VLOOKUP(B334,'Results_GPT5.2Low'!B:P,15,0),1000)) -> 1000 | Q334: =VLOOKUP(C334,Locs!A:C,3,0) -> 48 | R334: =VLOOKUP(C334,Locs!A:F,6,0) -> 2
B335: =C335&"-"&D335 -> task_id_632.dfy-4 | C335: task_id_632.dfy | D335: 4 | E335: =MAX(IFERROR(VLOOKUP(B335,'Results_ClaudeOpus4.5'!B:E,4,0),0),IFERROR(VLOOKUP(B335,'Results_GPT5.2Low'!B:E,4,0),0)) -> 0 | F335: =MAX('Results_ClaudeOpus4.5'!F335,'Results_GPT5.2Low'!F335) -> 10.3103 | G335: =MAX('Results_ClaudeOpus4.5'!G335,'Results_GPT5.2Low'!G335) -> 13.4955 | H335: =MAX(IFERROR(VLOOKUP(B335,'Results_ClaudeOpus4.5'!B:H,7,0),0),IFERROR(VLOOKUP(B335,'Results_GPT5.2Low'!B:H,7,0),0)) -> 35.8202 | I335: 1 | J335: 0 | K335: 0 | L335: =COUNTIFS(C:C,C335,E:E,1) -> 0 | M335: =_xlfn.MINIFS(D:D,C:C,C335,E:E,1) -> 0 | N335: =CHOOSE(L335+1,0,2/3,1,1) -> 0 | O335: =IF(L335>0,1,0) -> 0 | P335: =MIN(IF(IFERROR(VLOOKUP(B335,'Results_ClaudeOpus4.5'!B:E,4,0),0)=1,VLOOKUP(B335,'Results_ClaudeOpus4.5'!B:P,15,0),1000),IF(IFERROR(VLOOKUP(B335,'Results_GPT5.2Low'!B:E,4,0),0)=1,VLOOKUP(B335,'Results_GPT5.2Low'!B:P,15,0),1000)) -> 1000 | Q335: =VLOOKUP(C335,Locs!A:C,3,0) -> 48 | R335: =VLOOKUP(C335,Locs!A:F,6,0) -> 2
B336: =C336&"-"&D336 -> task_id_632.dfy-5 | C336: task_id_632.dfy | D336: 5 | E336: =MAX(IFERROR(VLOOKUP(B336,'Results_ClaudeOpus4.5'!B:E,4,0),0),IFERROR(VLOOKUP(B336,'Results_GPT5.2Low'!B:E,4,0),0)) -> 0 | F336: =MAX('Results_ClaudeOpus4.5'!F336,'Results_GPT5.2Low'!F336) -> 31.7552 | G336: =MAX('Results_ClaudeOpus4.5'!G336,'Results_GPT5.2Low'!G336) -> 1.9592 | H336: =MAX(IFERROR(VLOOKUP(B336,'Results_ClaudeOpus4.5'!B:H,7,0),0),IFERROR(VLOOKUP(B336,'Results_GPT5.2Low'!B:H,7,0),0)) -> 66.3743 | I336: 1 | J336: 0 | K336: 0 | L336: =COUNTIFS(C:C,C336,E:E,1) -> 0 | M336: =_xlfn.MINIFS(D:D,C:C,C336,E:E,1) -> 0 | N336: =CHOOSE(L336+1,0,2/3,1,1) -> 0 | O336: =IF(L336>0,1,0) -> 0 | P336: =MIN(IF(IFERROR(VLOOKUP(B336,'Results_ClaudeOpus4.5'!B:E,4,0),0)=1,VLOOKUP(B336,'Results_ClaudeOpus4.5'!B:P,15,0),1000),IF(IFERROR(VLOOKUP(B336,'Results_GPT5.2Low'!B:E,4,0),0)=1,VLOOKUP(B336,'Results_GPT5.2Low'!B:P,15,0),1000)) -> 1000 | Q336: =VLOOKUP(C336,Locs!A:C,3,0) -> 48 | R336: =VLOOKUP(C336,Locs!A:F,6,0) -> 2
B337: =C337&"-"&D337 -> task_id_644.dfy-1 | C337: task_id_644.dfy | D337: 1 | E337: =MAX(IFERROR(VLOOKUP(B337,'Results_ClaudeOpus4.5'!B:E,4,0),0),IFERROR(VLOOKUP(B337,'Results_GPT5.2Low'!B:E,4,0),0)) -> 1 | F337: =MAX('Results_ClaudeOpus4.5'!F337,'Results_GPT5.2Low'!F337) -> 45.4918 | G337: =MAX('Results_ClaudeOpus4.5'!G337,'Results_GPT5.2Low'!G337) -> 1.7295 | H337: =MAX(IFERROR(VLOOKUP(B337,'Results_ClaudeOpus4.5'!B:H,7,0),0),IFERROR(VLOOKUP(B337,'Results_GPT5.2Low'!B:H,7,0),0)) -> 8.4595 | I337: 1 | J337: 0 | K337: 0 | L337: =COUNTIFS(C:C,C337,E:E,1) -> 3 | M337: =_xlfn.MINIFS(D:D,C:C,C337,E:E,1) -> 1 | N337: =CHOOSE(L337+1,0,2/3,1,1) -> 1 | O337: =IF(L337>0,1,0) -> 1 | P337: =MIN(IF(IFERROR(VLOOKUP(B337,'Results_ClaudeOpus4.5'!B:E,4,0),0)=1,VLOOKUP(B337,'Results_ClaudeOpus4.5'!B:P,15,0),1000),IF(IFERROR(VLOOKUP(B337,'Results_GPT5.2Low'!B:E,4,0),0)=1,VLOOKUP(B337,'Results_GPT5.2Low'!B:P,15,0),1000)) -> 33 | Q337: =VLOOKUP(C337,Locs!A:C,3,0) -> 31 | R337: =VLOOKUP(C337,Locs!A:F,6,0) -> 0
B338: =C338&"-"&D338 -> task_id_644.dfy-2 | C338: task_id_644.dfy | D338: 2 | E338: =MAX(IFERROR(VLOOKUP(B338,'Results_ClaudeOpus4.5'!B:E,4,0),0),IFERROR(VLOOKUP(B338,'Results_GPT5.2Low'!B:E,4,0),0)) -> 1 | F338: =MAX('Results_ClaudeOpus4.5'!F338,'Results_GPT5.2Low'!F338) -> 30.6537 | G338: =MAX('Results_ClaudeOpus4.5'!G338,'Results_GPT5.2Low'!G338) -> 1.4259 | H338: =MAX(IFERROR(VLOOKUP(B338,'Results_ClaudeOpus4.5'!B:H,7,0),0),IFERROR(VLOOKUP(B338,'Results_GPT5.2Low'!B:H,7,0),0)) -> 16.1403 | I338: 1 | J338: 0 | K338: 0 | L338: =COUNTIFS(C:C,C338,E:E,1) -> 3 | M338: =_xlfn.MINIFS(D:D,C:C,C338,E:E,1) -> 1 | N338: =CHOOSE(L338+1,0,2/3,1,1) -> 1 | O338: =IF(L338>0,1,0) -> 1 | P338: =MIN(IF(IFERROR(VLOOKUP(B338,'Results_ClaudeOpus4.5'!B:E,4,0),0)=1,VLOOKUP(B338,'Results_ClaudeOpus4.5'!B:P,15,0),1000),IF(IFERROR(VLOOKUP(B338,'Results_GPT5.2Low'!B:E,4,0),0)=1,VLOOKUP(B338,'Results_GPT5.2Low'!B:P,15,0),1000)) -> 33 | Q338: =VLOOKUP(C338,Locs!A:C,3,0) -> 31 | R338: =VLOOKUP(C338,Locs!A:F,6,0) -> 0
B339: =C339&"-"&D339 -> task_id_644.dfy-3 | C339: task_id_644.dfy | D339: 3 | E339: =MAX(IFERROR(VLOOKUP(B339,'Results_ClaudeOpus4.5'!B:E,4,0),0),IFERROR(VLOOKUP(B339,'Results_GPT5.2Low'!B:E,4,0),0)) -> 1 | F339: =MAX('Results_ClaudeOpus4.5'!F339,'Results_GPT5.2Low'!F339) -> 63.0239 | G339: =MAX('Results_ClaudeOpus4.5'!G339,'Results_GPT5.2Low'!G339) -> 2.2719 | H339: =MAX(IFERROR(VLOOKUP(B339,'Results_ClaudeOpus4.5'!B:H,7,0),0),IFERROR(VLOOKUP(B339,'Results_GPT5.2Low'!B:H,7,0),0)) -> 10.0568 | I339: 1 | J339: 0 | K339: 0 | L339: =COUNTIFS(C:C,C339,E:E,1) -> 3 | M339: =_xlfn.MINIFS(D:D,C:C,C339,E:E,1) -> 1 | N339: =CHOOSE(L339+1,0,2/3,1,1) -> 1 | O339: =IF(L339>0,1,0) -> 1 | P339: =MIN(IF(IFERROR(VLOOKUP(B339,'Results_ClaudeOpus4.5'!B:E,4,0),0)=1,VLOOKUP(B339,'Results_ClaudeOpus4.5'!B:P,15,0),1000),IF(IFERROR(VLOOKUP(B339,'Results_GPT5.2Low'!B:E,4,0),0)=1,VLOOKUP(B339,'Results_GPT5.2Low'!B:P,15,0),1000)) -> 33 | Q339: =VLOOKUP(C339,Locs!A:C,3,0) -> 31 | R339: =VLOOKUP(C339,Locs!A:F,6,0) -> 0
B340: =C340&"-"&D340 -> task_id_69.dfy-1 | C340: task_id_69.dfy | D340: 1 | E340: =MAX(IFERROR(VLOOKUP(B340,'Results_ClaudeOpus4.5'!B:E,4,0),0),IFERROR(VLOOKUP(B340,'Results_GPT5.2Low'!B:E,4,0),0)) -> 1 | F340: =MAX('Results_ClaudeOpus4.5'!F340,'Results_GPT5.2Low'!F340) -> 76.0011 | G340: =MAX('Results_ClaudeOpus4.5'!G340,'Results_GPT5.2Low'!G340) -> 1.3566 | H340: =MAX(IFERROR(VLOOKUP(B340,'Results_ClaudeOpus4.5'!B:H,7,0),0),IFERROR(VLOOKUP(B340,'Results_GPT5.2Low'!B:H,7,0),0)) -> 15.4214 | I340: 1 | J340: 0 | K340: 0 | L340: =COUNTIFS(C:C,C340,E:E,1) -> 3 | M340: =_xlfn.MINIFS(D:D,C:C,C340,E:E,1) -> 1 | N340: =CHOOSE(L340+1,0,2/3,1,1) -> 1 | O340: =IF(L340>0,1,0) -> 1 | P340: =MIN(IF(IFERROR(VLOOKUP(B340,'Results_ClaudeOpus4.5'!B:E,4,0),0)=1,VLOOKUP(B340,'Results_ClaudeOpus4.5'!B:P,15,0),1000),IF(IFERROR(VLOOKUP(B340,'Results_GPT5.2Low'!B:E,4,0),0)=1,VLOOKUP(B340,'Results_GPT5.2Low'!B:P,15,0),1000)) -> 27 | Q340: =VLOOKUP(C340,Locs!A:C,3,0) -> 27 | R340: =VLOOKUP(C340,Locs!A:F,6,0) -> 0
B341: =C341&"-"&D341 -> task_id_69.dfy-2 | C341: task_id_69.dfy | D341: 2 | E341: =MAX(IFERROR(VLOOKUP(B341,'Results_ClaudeOpus4.5'!B:E,4,0),0),IFERROR(VLOOKUP(B341,'Results_GPT5.2Low'!B:E,4,0),0)) -> 1 | F341: =MAX('Results_ClaudeOpus4.5'!F341,'Results_GPT5.2Low'!F341) -> 13.8553 | G341: =MAX('Results_ClaudeOpus4.5'!G341,'Results_GPT5.2Low'!G341) -> 1.8594 | H341: =MAX(IFERROR(VLOOKUP(B341,'Results_ClaudeOpus4.5'!B:H,7,0),0),IFERROR(VLOOKUP(B341,'Results_GPT5.2Low'!B:H,7,0),0)) -> 7.3747 | I341: 1 | J341: 0 | K341: 0 | L341: =COUNTIFS(C:C,C341,E:E,1) -> 3 | M341: =_xlfn.MINIFS(D:D,C:C,C341,E:E,1) -> 1 | N341: =CHOOSE(L341+1,0,2/3,1,1) -> 1 | O341: =IF(L341>0,1,0) -> 1 | P341: =MIN(IF(IFERROR(VLOOKUP(B341,'Results_ClaudeOpus4.5'!B:E,4,0),0)=1,VLOOKUP(B341,'Results_ClaudeOpus4.5'!B:P,15,0),1000),IF(IFERROR(VLOOKUP(B341,'Results_GPT5.2Low'!B:E,4,0),0)=1,VLOOKUP(B341,'Results_GPT5.2Low'!B:P,15,0),1000)) -> 27 | Q341: =VLOOKUP(C341,Locs!A:C,3,0) -> 27 | R341: =VLOOKUP(C341,Locs!A:F,6,0) -> 0
B342: =C342&"-"&D342 -> task_id_69.dfy-3 | C342: task_id_69.dfy | D342: 3 | E342: =MAX(IFERROR(VLOOKUP(B342,'Results_ClaudeOpus4.5'!B:E,4,0),0),IFERROR(VLOOKUP(B342,'Results_GPT5.2Low'!B:E,4,0),0)) -> 1 | F342: =MAX('Results_ClaudeOpus4.5'!F342,'Results_GPT5.2Low'!F342) -> 25.2172 | G342: =MAX('Results_ClaudeOpus4.5'!G342,'Results_GPT5.2Low'!G342) -> 1.9384 | H342: =MAX(IFERROR(VLOOKUP(B342,'Results_ClaudeOpus4.5'!B:H,7,0),0),IFERROR(VLOOKUP(B342,'Results_GPT5.2Low'!B:H,7,0),0)) -> 8.588 | I342: 1 | J342: 0 | K342: 0 | L342: =COUNTIFS(C:C,C342,E:E,1) -> 3 | M342: =_xlfn.MINIFS(D:D,C:C,C342,E:E,1) -> 1 | N342: =CHOOSE(L342+1,0,2/3,1,1) -> 1 | O342: =IF(L342>0,1,0) -> 1 | P342: =MIN(IF(IFERROR(VLOOKUP(B342,'Results_ClaudeOpus4.5'!B:E,4,0),0)=1,VLOOKUP(B342,'Results_ClaudeOpus4.5'!B:P,15,0),1000),IF(IFERROR(VLOOKUP(B342,'Results_GPT5.2Low'!B:E,4,0),0)=1,VLOOKUP(B342,'Results_GPT5.2Low'!B:P,15,0),1000)) -> 27 | Q342: =VLOOKUP(C342,Locs!A:C,3,0) -> 27 | R342: =VLOOKUP(C342,Locs!A:F,6,0) -> 0
B343: =C343&"-"&D343 -> task_id_70.dfy-1 | C343: task_id_70.dfy | D343: 1 | E343: =MAX(IFERROR(VLOOKUP(B343,'Results_ClaudeOpus4.5'!B:E,4,0),0),IFERROR(VLOOKUP(B343,'Results_GPT5.2Low'!B:E,4,0),0)) -> 0 | F343: =MAX('Results_ClaudeOpus4.5'!F343,'Results_GPT5.2Low'!F343) -> 15.5712 | G343: =MAX('Results_ClaudeOpus4.5'!G343,'Results_GPT5.2Low'!G343) -> 1.8225 | H343: =MAX(IFERROR(VLOOKUP(B343,'Results_ClaudeOpus4.5'!B:H,7,0),0),IFERROR(VLOOKUP(B343,'Results_GPT5.2Low'!B:H,7,0),0)) -> 14.7941 | I343: 1 | J343: 0 | K343: 0 | L343: =COUNTIFS(C:C,C343,E:E,1) -> 0 | M343: =_xlfn.MINIFS(D:D,C:C,C343,E:E,1) -> 0 | N343: =CHOOSE(L343+1,0,2/3,1,1) -> 0 | O343: =IF(L343>0,1,0) -> 0 | P343: =MIN(IF(IFERROR(VLOOKUP(B343,'Results_ClaudeOpus4.5'!B:E,4,0),0)=1,VLOOKUP(B343,'Results_ClaudeOpus4.5'!B:P,15,0),1000),IF(IFERROR(VLOOKUP(B343,'Results_GPT5.2Low'!B:E,4,0),0)=1,VLOOKUP(B343,'Results_GPT5.2Low'!B:P,15,0),1000)) -> 1000 | Q343: =VLOOKUP(C343,Locs!A:C,3,0) -> 28 | R343: =VLOOKUP(C343,Locs!A:F,6,0) -> 1
... B443: =C443&"-"&D443 -> task_id_95.dfy-5 | C443: task_id_95.dfy | D443: 5 | E443: =MAX(IFERROR(VLOOKUP(B443,'Results_ClaudeOpus4.5'!B:E,4,0),0),IFERROR(VLOOKUP(B443,'Results_GPT5.2Low'!B:E,4,0),0)) -> 0 | F443: =MAX('Results_ClaudeOpus4.5'!F443,'Results_GPT5.2Low'!F443) -> 16.8799 | G443: =MAX('Results_ClaudeOpus4.5'!G443,'Results_GPT5.2Low'!G443) -> 2.251 | H443: =MAX(IFERROR(VLOOKUP(B443,'Results_ClaudeOpus4.5'!B:H,7,0),0),IFERROR(VLOOKUP(B443,'Results_GPT5.2Low'!B:H,7,0),0)) -> 14.8361 | I443: 1 | J443: 0 | K443: 0 | L443: =COUNTIFS(C:C,C443,E:E,1) -> 0 | M443: =_xlfn.MINIFS(D:D,C:C,C443,E:E,1) -> 0 | N443: =CHOOSE(L443+1,0,2/3,1,1) -> 0 | O443: =IF(L443>0,1,0) -> 0 | P443: =MIN(IF(IFERROR(VLOOKUP(B443,'Results_ClaudeOpus4.5'!B:E,4,0),0)=1,VLOOKUP(B443,'Results_ClaudeOpus4.5'!B:P,15,0),1000),IF(IFERROR(VLOOKUP(B443,'Results_GPT5.2Low'!B:E,4,0),0)=1,VLOOKUP(B443,'Results_GPT5.2Low'!B:P,15,0),1000)) -> 1000 | Q443: =VLOOKUP(C443,Locs!A:C,3,0) -> 32 | R443: =VLOOKUP(C443,Locs!A:F,6,0) -> 6

Sheet Results_ClaudeOpus4.5
A1: Ordering | B1: Key | C1: Filename | D1: Attempt | E1: Success | F1: Time Gen | G1: Time Ver | H1: Time API Call | I1: Success Merged Original | J1: Success Raw | K1: Success Postprocessed | L1: C | M1: Attempts to Success | N1: 2 | O1: 3 | P1: LOC llm | Q1: LOC man | R1: Helpers + lemmas | S1: n to pass | T1: File | U1: LOC
A2: 1 | B2: =C2&"-"&D2 -> BinarySearch.dfy-1 | C2: BinarySearch.dfy | D2: 1 | E2: 1 | F2: 10.2125 | G2: 1.6528 | H2: 10.2105 | I2: 1 | J2: 1 | K2: 1 | L2: =COUNTIFS(C:C,C2,E:E,1) -> 3 | M2: =_xlfn.MINIFS(D:D,C:C,C2,E:E,1) -> 1 | N2: =CHOOSE(L2+1,0,2/3,1,1) -> 1 | O2: =IF(L2>0,1,0) -> 1 | P2: =VLOOKUP(LEFT(C2,LEN(C2)-4)&"_"&D2&"_llm.dfy",T:U,2,0) -> 47 | Q2: =VLOOKUP(C2,Locs!A:C,3,0) -> 38 | R2: =VLOOKUP(C2,Locs!A:F,6,0) -> 0 | S2: =_xlfn.MINIFS(D:D,C:C,C2,E:E,1) -> 1 | T2: BinarySearch_1_llm.dfy | U2: 47
A3: 2 | B3: =C3&"-"&D3 -> BinarySearch.dfy-2 | C3: BinarySearch.dfy | D3: 2 | E3: 1 | F3: 7.9071 | G3: 2.2863 | H3: 7.9051 | I3: 1 | J3: 1 | K3: 1 | L3: =COUNTIFS(C:C,C3,E:E,1) -> 3 | M3: =_xlfn.MINIFS(D:D,C:C,C3,E:E,1) -> 1 | N3: =CHOOSE(L3+1,0,2/3,1,1) -> 1 | O3: =IF(L3>0,1,0) -> 1 | P3: =VLOOKUP(LEFT(C3,LEN(C3)-4)&"_"&D3&"_llm.dfy",T:U,2,0) -> 47 | Q3: =VLOOKUP(C3,Locs!A:C,3,0) -> 38 | R3: =VLOOKUP(C3,Locs!A:F,6,0) -> 0 | S3: =_xlfn.MINIFS(D:D,C:C,C3,E:E,1) -> 1 | T3: BinarySearch_2_llm.dfy | U3: 47
A4: 3 | B4: =C4&"-"&D4 -> BinarySearch.dfy-3 | C4: BinarySearch.dfy | D4: 3 | E4: 1 | F4: 7.4215 | G4: 1.6505 | H4: 7.4191 | I4: 1 | J4: 1 | K4: 1 | L4: =COUNTIFS(C:C,C4,E:E,1) -> 3 | M4: =_xlfn.MINIFS(D:D,C:C,C4,E:E,1) -> 1 | N4: =CHOOSE(L4+1,0,2/3,1,1) -> 1 | O4: =IF(L4>0,1,0) -> 1 | P4: =VLOOKUP(LEFT(C4,LEN(C4)-4)&"_"&D4&"_llm.dfy",T:U,2,0) -> 47 | Q4: =VLOOKUP(C4,Locs!A:C,3,0) -> 38 | R4: =VLOOKUP(C4,Locs!A:F,6,0) -> 0 | S4: =_xlfn.MINIFS(D:D,C:C,C4,E:E,1) -> 1 | T4: BinarySearch_3_llm.dfy | U4: 47
A5: 4 | B5: =C5&"-"&D5 -> BubbleSort.dfy-1 | C5: BubbleSort.dfy | D5: 1 | E5: 0 | F5: 11.5263 | G5: 4.4049 | H5: 11.5238 | I5: -1 | J5: 0 | K5: 0 | L5: =COUNTIFS(C:C,C5,E:E,1) -> 0 | M5: =_xlfn.MINIFS(D:D,C:C,C5,E:E,1) -> 0 | N5: =CHOOSE(L5+1,0,2/3,1,1) -> 0 | O5: =IF(L5>0,1,0) -> 0 | P5: =VLOOKUP(LEFT(C5,LEN(C5)-4)&"_"&D5&"_llm.dfy",T:U,2,0) -> 53 | Q5: =VLOOKUP(C5,Locs!A:C,3,0) -> 44 | R5: =VLOOKUP(C5,Locs!A:F,6,0) -> 1 | S5: =_xlfn.MINIFS(D:D,C:C,C5,E:E,1) -> 0 | T5: BubbleSort_1_llm.dfy | U5: 53
A6: 5 | B6: =C6&"-"&D6 -> BubbleSort.dfy-2 | C6: BubbleSort.dfy | D6: 2 | E6: 0 | F6: 9.3543 | G6: 2.2486 | H6: 9.3506 | I6: -1 | J6: 0 | K6: 0 | L6: =COUNTIFS(C:C,C6,E:E,1) -> 0 | M6: =_xlfn.MINIFS(D:D,C:C,C6,E:E,1) -> 0 | N6: =CHOOSE(L6+1,0,2/3,1,1) -> 0 | O6: =IF(L6>0,1,0) -> 0 | P6: =VLOOKUP(LEFT(C6,LEN(C6)-4)&"_"&D6&"_llm.dfy",T:U,2,0) -> 51 | Q6: =VLOOKUP(C6,Locs!A:C,3,0) -> 44 | R6: =VLOOKUP(C6,Locs!A:F,6,0) -> 1 | S6: =_xlfn.MINIFS(D:D,C:C,C6,E:E,1) -> 0 | T6: BubbleSort_2_llm.dfy | U6: 51
A7: 6 | B7: =C7&"-"&D7 -> BubbleSort.dfy-3 | C7: BubbleSort.dfy | D7: 3 | E7: 0 | F7: 8.8028 | G7: 2.5997 | H7: 8.8014 | I7: -1 | J7: 0 | K7: 0 | L7: =COUNTIFS(C:C,C7,E:E,1) -> 0 | M7: =_xlfn.MINIFS(D:D,C:C,C7,E:E,1) -> 0 | N7: =CHOOSE(L7+1,0,2/3,1,1) -> 0 | O7: =IF(L7>0,1,0) -> 0 | P7: =VLOOKUP(LEFT(C7,LEN(C7)-4)&"_"&D7&"_llm.dfy",T:U,2,0) -> 50 | Q7: =VLOOKUP(C7,Locs!A:C,3,0) -> 44 | R7: =VLOOKUP(C7,Locs!A:F,6,0) -> 1 | S7: =_xlfn.MINIFS(D:D,C:C,C7,E:E,1) -> 0 | T7: BubbleSort_3_llm.dfy | U7: 50
A8: 7 | B8: =C8&"-"&D8 -> BubbleSort.dfy-4 | C8: BubbleSort.dfy | D8: 4 | E8: 0 | F8: 11.4575 | G8: 4.2118 | H8: 11.4349 | I8: -1 | J8: 0 | K8: 0 | L8: =COUNTIFS(C:C,C8,E:E,1) -> 0 | M8: =_xlfn.MINIFS(D:D,C:C,C8,E:E,1) -> 0 | N8: =CHOOSE(L8+1,0,2/3,1,1) -> 0 | O8: =IF(L8>0,1,0) -> 0 | P8: =VLOOKUP(LEFT(C8,LEN(C8)-4)&"_"&D8&"_llm.dfy",T:U,2,0) -> 50 | Q8: =VLOOKUP(C8,Locs!A:C,3,0) -> 44 | R8: =VLOOKUP(C8,Locs!A:F,6,0) -> 1 | S8: =_xlfn.MINIFS(D:D,C:C,C8,E:E,1) -> 0 | T8: BubbleSort_4_llm.dfy | U8: 50
A9: 8 | B9: =C9&"-"&D9 -> BubbleSort.dfy-5 | C9: BubbleSort.dfy | D9: 5 | E9: 0 | F9: 10.5545 | G9: 2.4522 | H9: 10.5525 | I9: -1 | J9: 0 | K9: 0 | L9: =COUNTIFS(C:C,C9,E:E,1) -> 0 | M9: =_xlfn.MINIFS(D:D,C:C,C9,E:E,1) -> 0 | N9: =CHOOSE(L9+1,0,2/3,1,1) -> 0 | O9: =IF(L9>0,1,0) -> 0 | P9: =VLOOKUP(LEFT(C9,LEN(C9)-4)&"_"&D9&"_llm.dfy",T:U,2,0) -> 46 | Q9: =VLOOKUP(C9,Locs!A:C,3,0) -> 44 | R9: =VLOOKUP(C9,Locs!A:F,6,0) -> 1 | S9: =_xlfn.MINIFS(D:D,C:C,C9,E:E,1) -> 0 | T9: BubbleSort_5_llm.dfy | U9: 46
A10: 9 | B10: =C10&"-"&D10 -> Catalan.dfy-1 | C10: Catalan.dfy | D10: 1 | E10: 1 | F10: 5.47 | G10: 0.7243 | H10: 5.4676 | I10: 1 | J10: 1 | K10: 1 | L10: =COUNTIFS(C:C,C10,E:E,1) -> 3 | M10: =_xlfn.MINIFS(D:D,C:C,C10,E:E,1) -> 1 | N10: =CHOOSE(L10+1,0,2/3,1,1) -> 1 | O10: =IF(L10>0,1,0) -> 1 | P10: =VLOOKUP(LEFT(C10,LEN(C10)-4)&"_"&D10&"_llm.dfy",T:U,2,0) -> 30 | Q10: =VLOOKUP(C10,Locs!A:C,3,0) -> 28 | R10: =VLOOKUP(C10,Locs!A:F,6,0) -> 0 | S10: =_xlfn.MINIFS(D:D,C:C,C10,E:E,1) -> 1 | T10: Catalan_1_llm.dfy | U10: 30
A11: 10 | B11: =C11&"-"&D11 -> Catalan.dfy-2 | C11: Catalan.dfy | D11: 2 | E11: 1 | F11: 5.7983 | G11: 0.7238 | H11: 5.7967 | I11: 1 | J11: 1 | K11: 1 | L11: =COUNTIFS(C:C,C11,E:E,1) -> 3 | M11: =_xlfn.MINIFS(D:D,C:C,C11,E:E,1) -> 1 | N11: =CHOOSE(L11+1,0,2/3,1,1) -> 1 | O11: =IF(L11>0,1,0) -> 1 | P11: =VLOOKUP(LEFT(C11,LEN(C11)-4)&"_"&D11&"_llm.dfy",T:U,2,0) -> 30 | Q11: =VLOOKUP(C11,Locs!A:C,3,0) -> 28 | R11: =VLOOKUP(C11,Locs!A:F,6,0) -> 0 | S11: =_xlfn.MINIFS(D:D,C:C,C11,E:E,1) -> 1 | T11: Catalan_2_llm.dfy | U11: 30
A12: 11 | B12: =C12&"-"&D12 -> Catalan.dfy-3 | C12: Catalan.dfy | D12: 3 | E12: 1 | F12: 9.48 | G12: 0.7347 | H12: 9.4738 | I12: 1 | J12: 1 | K12: 1 | L12: =COUNTIFS(C:C,C12,E:E,1) -> 3 | M12: =_xlfn.MINIFS(D:D,C:C,C12,E:E,1) -> 1 | N12: =CHOOSE(L12+1,0,2/3,1,1) -> 1 | O12: =IF(L12>0,1,0) -> 1 | P12: =VLOOKUP(LEFT(C12,LEN(C12)-4)&"_"&D12&"_llm.dfy",T:U,2,0) -> 30 | Q12: =VLOOKUP(C12,Locs!A:C,3,0) -> 28 | R12: =VLOOKUP(C12,Locs!A:F,6,0) -> 0 | S12: =_xlfn.MINIFS(D:D,C:C,C12,E:E,1) -> 1 | T12: Catalan_3_llm.dfy | U12: 30
A13: 12 | B13: =C13&"-"&D13 -> CombNK.dfy-1 | C13: CombNK.dfy | D13: 1 | E13: 0 | F13: 9.2777 | G13: 1.7221 | H13: 9.2754 | I13: -1 | J13: 0 | K13: 0 | L13: =COUNTIFS(C:C,C13,E:E,1) -> 0 | M13: =_xlfn.MINIFS(D:D,C:C,C13,E:E,1) -> 0 | N13: =CHOOSE(L13+1,0,2/3,1,1) -> 0 | O13: =IF(L13>0,1,0) -> 0 | P13: =VLOOKUP(LEFT(C13,LEN(C13)-4)&"_"&D13&"_llm.dfy",T:U,2,0) -> 52 | Q13: =VLOOKUP(C13,Locs!A:C,3,0) -> 38 | R13: =VLOOKUP(C13,Locs!A:F,6,0) -> 0 | S13: =_xlfn.MINIFS(D:D,C:C,C13,E:E,1) -> 0 | T13: CombNK_1_llm.dfy | U13: 52
... A331: 330 | B331: =C331&"-"&D331 -> task_id_629.dfy-3 | C331: task_id_629.dfy | D331: 3 | E331: 1 | F331: 8.2612 | G331: 2.4806 | H331: 8.2567 | I331: 1 | J331: 1 | K331: 1 | L331: =COUNTIFS(C:C,C331,E:E,1) -> 3 | M331: =_xlfn.MINIFS(D:D,C:C,C331,E:E,1) -> 1 | N331: =CHOOSE(L331+1,0,2/3,1,1) -> 1 | O331: =IF(L331>0,1,0) -> 1 | P331: =VLOOKUP(LEFT(C331,LEN(C331)-4)&"_"&D331&"_llm.dfy",T:U,2,0) -> 45 | Q331: =VLOOKUP(C331,Locs!A:C,3,0) -> 49 | R331: =VLOOKUP(C331,Locs!A:F,6,0) -> 2 | S331: =_xlfn.MINIFS(D:D,C:C,C331,E:E,1) -> 1 | T331: task_id_62_5_llm.dfy | U331: 26
B332: =C332&"-"&D332 -> task_id_632.dfy-1 | C332: task_id_632.dfy | D332: 1 | E332: 0 | F332: 8.8456 | G332: 2.6992 | H332: 8.8228 | I332: 0 | J332: 0 | K332: 0 | L332: =COUNTIFS(C:C,C332,E:E,1) -> 0 | M332: =_xlfn.MINIFS(D:D,C:C,C332,E:E,1) -> 0 | N332: =CHOOSE(L332+1,0,2/3,1,1) -> 0 | O332: =IF(L332>0,1,0) -> 0 | P332: =VLOOKUP(LEFT(C332,LEN(C332)-4)&"_"&D332&"_llm.dfy",T:U,2,0) -> 53 | Q332: =VLOOKUP(C332,Locs!A:C,3,0) -> 48 | R332: =VLOOKUP(C332,Locs!A:F,6,0) -> 2 | S332: =_xlfn.MINIFS(D:D,C:C,C332,E:E,1) -> 0 | T332: task_id_632_1_llm.dfy | U332: 53
B333: =C333&"-"&D333 -> task_id_632.dfy-2 | C333: task_id_632.dfy | D333: 2 | E333: 0 | F333: 11.2195 | G333: 2.8043 | H333: 11.2167 | I333: 0 | J333: 0 | K333: 0 | L333: =COUNTIFS(C:C,C333,E:E,1) -> 0 | M333: =_xlfn.MINIFS(D:D,C:C,C333,E:E,1) -> 0 | N333: =CHOOSE(L333+1,0,2/3,1,1) -> 0 | O333: =IF(L333>0,1,0) -> 0 | P333: =VLOOKUP(LEFT(C333,LEN(C333)-4)&"_"&D333&"_llm.dfy",T:U,2,0) -> 53 | Q333: =VLOOKUP(C333,Locs!A:C,3,0) -> 48 | R333: =VLOOKUP(C333,Locs!A:F,6,0) -> 2 | S333: =_xlfn.MINIFS(D:D,C:C,C333,E:E,1) -> 0 | T333: task_id_632_2_llm.dfy | U333: 53
B334: =C334&"-"&D334 -> task_id_632.dfy-3 | C334: task_id_632.dfy | D334: 3 | E334: 0 | F334: 11.156 | G334: 2.6997 | H334: 11.1532 | I334: 0 | J334: 0 | K334: 0 | L334: =COUNTIFS(C:C,C334,E:E,1) -> 0 | M334: =_xlfn.MINIFS(D:D,C:C,C334,E:E,1) -> 0 | N334: =CHOOSE(L334+1,0,2/3,1,1) -> 0 | O334: =IF(L334>0,1,0) -> 0 | P334: =VLOOKUP(LEFT(C334,LEN(C334)-4)&"_"&D334&"_llm.dfy",T:U,2,0) -> 62 | Q334: =VLOOKUP(C334,Locs!A:C,3,0) -> 48 | R334: =VLOOKUP(C334,Locs!A:F,6,0) -> 2 | S334: =_xlfn.MINIFS(D:D,C:C,C334,E:E,1) -> 0 | T334: task_id_632_3_llm.dfy | U334: 62
B335: =C335&"-"&D335 -> task_id_632.dfy-4 | C335: task_id_632.dfy | D335: 4 | E335: 0 | F335: 10.2887 | G335: 13.4955 | H335: 10.2682 | I335: 0 | J335: 0 | K335: 0 | L335: =COUNTIFS(C:C,C335,E:E,1) -> 0 | M335: =_xlfn.MINIFS(D:D,C:C,C335,E:E,1) -> 0 | N335: =CHOOSE(L335+1,0,2/3,1,1) -> 0 | O335: =IF(L335>0,1,0) -> 0 | P335: =VLOOKUP(LEFT(C335,LEN(C335)-4)&"_"&D335&"_llm.dfy",T:U,2,0) -> 50 | Q335: =VLOOKUP(C335,Locs!A:C,3,0) -> 48 | R335: =VLOOKUP(C335,Locs!A:F,6,0) -> 2 | S335: =_xlfn.MINIFS(D:D,C:C,C335,E:E,1) -> 0 | T335: task_id_632_4_llm.dfy | U335: 50
B336: =C336&"-"&D336 -> task_id_632.dfy-5 | C336: task_id_632.dfy | D336: 5 | E336: 0 | F336: 12.8366 | G336: 1.9592 | H336: 12.8351 | I336: 0 | J336: 0 | K336: 0 | L336: =COUNTIFS(C:C,C336,E:E,1) -> 0 | M336: =_xlfn.MINIFS(D:D,C:C,C336,E:E,1) -> 0 | N336: =CHOOSE(L336+1,0,2/3,1,1) -> 0 | O336: =IF(L336>0,1,0) -> 0 | P336: =VLOOKUP(LEFT(C336,LEN(C336)-4)&"_"&D336&"_llm.dfy",T:U,2,0) -> 53 | Q336: =VLOOKUP(C336,Locs!A:C,3,0) -> 48 | R336: =VLOOKUP(C336,Locs!A:F,6,0) -> 2 | S336: =_xlfn.MINIFS(D:D,C:C,C336,E:E,1) -> 0 | T336: task_id_632_5_llm.dfy | U336: 53
B337: =C337&"-"&D337 -> task_id_644.dfy-1 | C337: task_id_644.dfy | D337: 1 | E337: 1 | F337: 8.1051 | G337: 1.3903 | H337: 8.0809 | I337: 1 | J337: 1 | K337: 1 | L337: =COUNTIFS(C:C,C337,E:E,1) -> 3 | M337: =_xlfn.MINIFS(D:D,C:C,C337,E:E,1) -> 1 | N337: =CHOOSE(L337+1,0,2/3,1,1) -> 1 | O337: =IF(L337>0,1,0) -> 1 | P337: =VLOOKUP(LEFT(C337,LEN(C337)-4)&"_"&D337&"_llm.dfy",T:U,2,0) -> 33 | Q337: =VLOOKUP(C337,Locs!A:C,3,0) -> 31 | R337: =VLOOKUP(C337,Locs!A:F,6,0) -> 0 | S337: =_xlfn.MINIFS(D:D,C:C,C337,E:E,1) -> 1 | T337: task_id_644_1_llm.dfy | U337: 33
B338: =C338&"-"&D338 -> task_id_644.dfy-2 | C338: task_id_644.dfy | D338: 2 | E338: 1 | F338: 6.7037 | G338: 1.4259 | H338: 6.7011 | I338: 1 | J338: 1 | K338: 1 | L338: =COUNTIFS(C:C,C338,E:E,1) -> 3 | M338: =_xlfn.MINIFS(D:D,C:C,C338,E:E,1) -> 1 | N338: =CHOOSE(L338+1,0,2/3,1,1) -> 1 | O338: =IF(L338>0,1,0) -> 1 | P338: =VLOOKUP(LEFT(C338,LEN(C338)-4)&"_"&D338&"_llm.dfy",T:U,2,0) -> 33 | Q338: =VLOOKUP(C338,Locs!A:C,3,0) -> 31 | R338: =VLOOKUP(C338,Locs!A:F,6,0) -> 0 | S338: =_xlfn.MINIFS(D:D,C:C,C338,E:E,1) -> 1 | T338: task_id_644_2_llm.dfy | U338: 33
B339: =C339&"-"&D339 -> task_id_644.dfy-3 | C339: task_id_644.dfy | D339: 3 | E339: 1 | F339: 6.703 | G339: 1.3257 | H339: 6.7005 | I339: 1 | J339: 1 | K339: 1 | L339: =COUNTIFS(C:C,C339,E:E,1) -> 3 | M339: =_xlfn.MINIFS(D:D,C:C,C339,E:E,1) -> 1 | N339: =CHOOSE(L339+1,0,2/3,1,1) -> 1 | O339: =IF(L339>0,1,0) -> 1 | P339: =VLOOKUP(LEFT(C339,LEN(C339)-4)&"_"&D339&"_llm.dfy",T:U,2,0) -> 33 | Q339: =VLOOKUP(C339,Locs!A:C,3,0) -> 31 | R339: =VLOOKUP(C339,Locs!A:F,6,0) -> 0 | S339: =_xlfn.MINIFS(D:D,C:C,C339,E:E,1) -> 1 | T339: task_id_644_3_llm.dfy | U339: 33
B340: =C340&"-"&D340 -> task_id_69.dfy-1 | C340: task_id_69.dfy | D340: 1 | E340: 1 | F340: 5.6912 | G340: 1.3566 | H340: 5.6747 | I340: 1 | J340: 1 | K340: 1 | L340: =COUNTIFS(C:C,C340,E:E,1) -> 3 | M340: =_xlfn.MINIFS(D:D,C:C,C340,E:E,1) -> 1 | N340: =CHOOSE(L340+1,0,2/3,1,1) -> 1 | O340: =IF(L340>0,1,0) -> 1 | P340: =VLOOKUP(LEFT(C340,LEN(C340)-4)&"_"&D340&"_llm.dfy",T:U,2,0) -> 27 | Q340: =VLOOKUP(C340,Locs!A:C,3,0) -> 27 | R340: =VLOOKUP(C340,Locs!A:F,6,0) -> 0 | S340: =_xlfn.MINIFS(D:D,C:C,C340,E:E,1) -> 1 | T340: task_id_69_1_llm.dfy | U340: 27
B341: =C341&"-"&D341 -> task_id_69.dfy-2 | C341: task_id_69.dfy | D341: 2 | E341: 1 | F341: 5.5762 | G341: 1.0916 | H341: 5.5733 | I341: 1 | J341: 1 | K341: 1 | L341: =COUNTIFS(C:C,C341,E:E,1) -> 3 | M341: =_xlfn.MINIFS(D:D,C:C,C341,E:E,1) -> 1 | N341: =CHOOSE(L341+1,0,2/3,1,1) -> 1 | O341: =IF(L341>0,1,0) -> 1 | P341: =VLOOKUP(LEFT(C341,LEN(C341)-4)&"_"&D341&"_llm.dfy",T:U,2,0) -> 27 | Q341: =VLOOKUP(C341,Locs!A:C,3,0) -> 27 | R341: =VLOOKUP(C341,Locs!A:F,6,0) -> 0 | S341: =_xlfn.MINIFS(D:D,C:C,C341,E:E,1) -> 1 | T341: task_id_69_2_llm.dfy | U341: 27
B342: =C342&"-"&D342 -> task_id_69.dfy-3 | C342: task_id_69.dfy | D342: 3 | E342: 1 | F342: 6.0927 | G342: 1.0891 | H342: 6.0899 | I342: 1 | J342: 1 | K342: 1 | L342: =COUNTIFS(C:C,C342,E:E,1) -> 3 | M342: =_xlfn.MINIFS(D:D,C:C,C342,E:E,1) -> 1 | N342: =CHOOSE(L342+1,0,2/3,1,1) -> 1 | O342: =IF(L342>0,1,0) -> 1 | P342: =VLOOKUP(LEFT(C342,LEN(C342)-4)&"_"&D342&"_llm.dfy",T:U,2,0) -> 27 | Q342: =VLOOKUP(C342,Locs!A:C,3,0) -> 27 | R342: =VLOOKUP(C342,Locs!A:F,6,0) -> 0 | S342: =_xlfn.MINIFS(D:D,C:C,C342,E:E,1) -> 1 | T342: task_id_69_3_llm.dfy | U342: 27
B343: =C343&"-"&D343 -> task_id_70.dfy-1 | C343: task_id_70.dfy | D343: 1 | E343: 0 | F343: 6.1783 | G343: 1.1777 | H343: 6.1579 | I343: 1 | J343: 0 | K343: 0 | L343: =COUNTIFS(C:C,C343,E:E,1) -> 0 | M343: =_xlfn.MINIFS(D:D,C:C,C343,E:E,1) -> 0 | N343: =CHOOSE(L343+1,0,2/3,1,1) -> 0 | O343: =IF(L343>0,1,0) -> 0 | P343: =VLOOKUP(LEFT(C343,LEN(C343)-4)&"_"&D343&"_llm.dfy",T:U,2,0) -> 27 | Q343: =VLOOKUP(C343,Locs!A:C,3,0) -> 28 | R343: =VLOOKUP(C343,Locs!A:F,6,0) -> 1 | S343: =_xlfn.MINIFS(D:D,C:C,C343,E:E,1) -> 0 | T343: task_id_70_1_llm.dfy | U343: 27
... B443: =C443&"-"&D443 -> task_id_95.dfy-5 | C443: task_id_95.dfy | D443: 5 | E443: 0 | F443: 5.7014 | G443: 1.2392 | H443: 5.6991 | I443: 1 | J443: 0 | K443: 0 | L443: =COUNTIFS(C:C,C443,E:E,1) -> 0 | M443: =_xlfn.MINIFS(D:D,C:C,C443,E:E,1) -> 0 | N443: =CHOOSE(L443+1,0,2/3,1,1) -> 0 | O443: =IF(L443>0,1,0) -> 0 | P443: =VLOOKUP(LEFT(C443,LEN(C443)-4)&"_"&D443&"_llm.dfy",T:U,2,0) -> 26 | Q443: =VLOOKUP(C443,Locs!A:C,3,0) -> 32 | R443: =VLOOKUP(C443,Locs!A:F,6,0) -> 6 | S443: =_xlfn.MINIFS(D:D,C:C,C443,E:E,1) -> 0 | T443: task_id_95_5_llm.dfy | U443: 26

Sheet Results_ClaudeOpus4.5T0
A1: Ordering | B1: Key | C1: Filename | D1: Attempt | E1: Success | F1: Time Gen | G1: Time Ver | H1: Time API Call | I1: Success Merged Original | J1: Success Raw | K1: Success Postprocessed | L1: C | M1: Attempts to Success | N1: 2 | O1: 3 | P1: LOC llm | Q1: LOC man | R1: Helpers + lemmas | S1: n to pass | T1: File | U1: LOC
A2: 1 | B2: =C2&"-"&D2 -> BinarySearch.dfy-1 | C2: BinarySearch.dfy | D2: 1 | E2: 1 | F2: 8.0322 | G2: 1.618 | H2: 8.026 | I2: 1 | J2: 1 | K2: 1 | L2: =COUNTIFS(C:C,C2,E:E,1) -> 1 | M2: =_xlfn.MINIFS(D:D,C:C,C2,E:E,1) -> 1 | N2: =CHOOSE(L2+1,0,2/3,1,1) -> 0.66666667 | O2: =IF(L2>0,1,0) -> 1 | P2: =VLOOKUP(LEFT(C2,LEN(C2)-4)&"_"&D2&"_llm.dfy",T:U,2,0) -> 47 | Q2: =VLOOKUP(C2,Locs!A:C,3,0) -> 38 | R2: =VLOOKUP(C2,Locs!A:F,6,0) -> 0 | S2: =_xlfn.MINIFS(D:D,C:C,C2,E:E,1) -> 1 | T2: BinarySearch_1_llm.dfy | U2: 47
A3: 2 | B3: =C3&"-"&D3 -> BubbleSort.dfy-1 | C3: BubbleSort.dfy | D3: 1 | E3: 0 | F3: 8.4695 | G3: 3.1899 | H3: 8.4664 | I3: -1 | J3: 0 | K3: 0 | L3: =COUNTIFS(C:C,C3,E:E,1) -> 0 | M3: =_xlfn.MINIFS(D:D,C:C,C3,E:E,1) -> 0 | N3: =CHOOSE(L3+1,0,2/3,1,1) -> 0 | O3: =IF(L3>0,1,0) -> 0 | P3: =VLOOKUP(LEFT(C3,LEN(C3)-4)&"_"&D3&"_llm.dfy",T:U,2,0) -> 50 | Q3: =VLOOKUP(C3,Locs!A:C,3,0) -> 44 | R3: =VLOOKUP(C3,Locs!A:F,6,0) -> 1 | S3: =_xlfn.MINIFS(D:D,C:C,C3,E:E,1) -> 0 | T3: BubbleSort_1_llm.dfy | U3: 50
A4: 3 | B4: =C4&"-"&D4 -> BubbleSort.dfy-2 | C4: BubbleSort.dfy | D4: 2 | E4: 0 | F4: 10.0118 | G4: 1.9507 | H4: 10.0103 | I4: -1 | J4: 0 | K4: 0 | L4: =COUNTIFS(C:C,C4,E:E,1) -> 0 | M4: =_xlfn.MINIFS(D:D,C:C,C4,E:E,1) -> 0 | N4: =CHOOSE(L4+1,0,2/3,1,1) -> 0 | O4: =IF(L4>0,1,0) -> 0 | P4: =VLOOKUP(LEFT(C4,LEN(C4)-4)&"_"&D4&"_llm.dfy",T:U,2,0) -> 52 | Q4: =VLOOKUP(C4,Locs!A:C,3,0) -> 44 | R4: =VLOOKUP(C4,Locs!A:F,6,0) -> 1 | S4: =_xlfn.MINIFS(D:D,C:C,C4,E:E,1) -> 0 | T4: BubbleSort_2_llm.dfy | U4: 52
A5: 4 | B5: =C5&"-"&D5 -> BubbleSort.dfy-3 | C5: BubbleSort.dfy | D5: 3 | E5: 0 | F5: 9.7688 | G5: 1.9624 | H5: 9.7621 | I5: -1 | J5: 0 | K5: 0 | L5: =COUNTIFS(C:C,C5,E:E,1) -> 0 | M5: =_xlfn.MINIFS(D:D,C:C,C5,E:E,1) -> 0 | N5: =CHOOSE(L5+1,0,2/3,1,1) -> 0 | O5: =IF(L5>0,1,0) -> 0 | P5: =VLOOKUP(LEFT(C5,LEN(C5)-4)&"_"&D5&"_llm.dfy",T:U,2,0) -> 52 | Q5: =VLOOKUP(C5,Locs!A:C,3,0) -> 44 | R5: =VLOOKUP(C5,Locs!A:F,6,0) -> 1 | S5: =_xlfn.MINIFS(D:D,C:C,C5,E:E,1) -> 0 | T5: BubbleSort_3_llm.dfy | U5: 52
A6: 5 | B6: =C6&"-"&D6 -> BubbleSort.dfy-4 | C6: BubbleSort.dfy | D6: 4 | E6: 0 | F6: 10.9235 | G6: 2.5396 | H6: 10.9223 | I6: -1 | J6: 0 | K6: 0 | L6: =COUNTIFS(C:C,C6,E:E,1) -> 0 | M6: =_xlfn.MINIFS(D:D,C:C,C6,E:E,1) -> 0 | N6: =CHOOSE(L6+1,0,2/3,1,1) -> 0 | O6: =IF(L6>0,1,0) -> 0 | P6: =VLOOKUP(LEFT(C6,LEN(C6)-4)&"_"&D6&"_llm.dfy",T:U,2,0) -> 50 | Q6: =VLOOKUP(C6,Locs!A:C,3,0) -> 44 | R6: =VLOOKUP(C6,Locs!A:F,6,0) -> 1 | S6: =_xlfn.MINIFS(D:D,C:C,C6,E:E,1) -> 0 | T6: BubbleSort_4_llm.dfy | U6: 50
A7: 6 | B7: =C7&"-"&D7 -> BubbleSort.dfy-5 | C7: BubbleSort.dfy | D7: 5 | E7: 0 | F7: 10.9743 | G7: 2.5306 | H7: 10.973 | I7: -1 | J7: 0 | K7: 0 | L7: =COUNTIFS(C:C,C7,E:E,1) -> 0 | M7: =_xlfn.MINIFS(D:D,C:C,C7,E:E,1) -> 0 | N7: =CHOOSE(L7+1,0,2/3,1,1) -> 0 | O7: =IF(L7>0,1,0) -> 0 | P7: =VLOOKUP(LEFT(C7,LEN(C7)-4)&"_"&D7&"_llm.dfy",T:U,2,0) -> 50 | Q7: =VLOOKUP(C7,Locs!A:C,3,0) -> 44 | R7: =VLOOKUP(C7,Locs!A:F,6,0) -> 1 | S7: =_xlfn.MINIFS(D:D,C:C,C7,E:E,1) -> 0 | T7: BubbleSort_5_llm.dfy | U7: 50
A8: 7 | B8: =C8&"-"&D8 -> Catalan.dfy-1 | C8: Catalan.dfy | D8: 1 | E8: 1 | F8: 5.4454 | G8: 0.728 | H8: 5.4115 | I8: 1 | J8: 1 | K8: 1 | L8: =COUNTIFS(C:C,C8,E:E,1) -> 1 | M8: =_xlfn.MINIFS(D:D,C:C,C8,E:E,1) -> 1 | N8: =CHOOSE(L8+1,0,2/3,1,1) -> 0.66666667 | O8: =IF(L8>0,1,0) -> 1 | P8: =VLOOKUP(LEFT(C8,LEN(C8)-4)&"_"&D8&"_llm.dfy",T:U,2,0) -> 30 | Q8: =VLOOKUP(C8,Locs!A:C,3,0) -> 28 | R8: =VLOOKUP(C8,Locs!A:F,6,0) -> 0 | S8: =_xlfn.MINIFS(D:D,C:C,C8,E:E,1) -> 1 | T8: Catalan_1_llm.dfy | U8: 30
A9: 8 | B9: =C9&"-"&D9 -> CombNK.dfy-1 | C9: CombNK.dfy | D9: 1 | E9: 0 | F9: 8.8938 | G9: 0.8114 | H9: 8.8689 | I9: -1 | J9: 0 | K9: 0 | L9: =COUNTIFS(C:C,C9,E:E,1) -> 0 | M9: =_xlfn.MINIFS(D:D,C:C,C9,E:E,1) -> 0 | N9: =CHOOSE(L9+1,0,2/3,1,1) -> 0 | O9: =IF(L9>0,1,0) -> 0 | P9: =VLOOKUP(LEFT(C9,LEN(C9)-4)&"_"&D9&"_llm.dfy",T:U,2,0) -> 40 | Q9: =VLOOKUP(C9,Locs!A:C,3,0) -> 38 | R9: =VLOOKUP(C9,Locs!A:F,6,0) -> 0 | S9: =_xlfn.MINIFS(D:D,C:C,C9,E:E,1) -> 0 | T9: CombNK_1_llm.dfy | U9: 40
A10: 9 | B10: =C10&"-"&D10 -> CombNK.dfy-2 | C10: CombNK.dfy | D10: 2 | E10: 0 | F10: 8.1422 | G10: 0.7708 | H10: 8.1357 | I10: -1 | J10: 0 | K10: 0 | L10: =COUNTIFS(C:C,C10,E:E,1) -> 0 | M10: =_xlfn.MINIFS(D:D,C:C,C10,E:E,1) -> 0 | N10: =CHOOSE(L10+1,0,2/3,1,1) -> 0 | O10: =IF(L10>0,1,0) -> 0 | P10: =VLOOKUP(LEFT(C10,LEN(C10)-4)&"_"&D10&"_llm.dfy",T:U,2,0) -> 40 | Q10: =VLOOKUP(C10,Locs!A:C,3,0) -> 38 | R10: =VLOOKUP(C10,Locs!A:F,6,0) -> 0 | S10: =_xlfn.MINIFS(D:D,C:C,C10,E:E,1) -> 0 | T10: CombNK_2_llm.dfy | U10: 40
A11: 10 | B11: =C11&"-"&D11 -> CombNK.dfy-3 | C11: CombNK.dfy | D11: 3 | E11: 0 | F11: 8.1184 | G11: 0.7884 | H11: 8.1126 | I11: -1 | J11: 0 | K11: 0 | L11: =COUNTIFS(C:C,C11,E:E,1) -> 0 | M11: =_xlfn.MINIFS(D:D,C:C,C11,E:E,1) -> 0 | N11: =CHOOSE(L11+1,0,2/3,1,1) -> 0 | O11: =IF(L11>0,1,0) -> 0 | P11: =VLOOKUP(LEFT(C11,LEN(C11)-4)&"_"&D11&"_llm.dfy",T:U,2,0) -> 40 | Q11: =VLOOKUP(C11,Locs!A:C,3,0) -> 38 | R11: =VLOOKUP(C11,Locs!A:F,6,0) -> 0 | S11: =_xlfn.MINIFS(D:D,C:C,C11,E:E,1) -> 0 | T11: CombNK_3_llm.dfy | U11: 40
A12: 11 | B12: =C12&"-"&D12 -> CombNK.dfy-4 | C12: CombNK.dfy | D12: 4 | E12: 0 | F12: 11.4738 | G12: 1.7035 | H12: 11.467 | I12: -1 | J12: 0 | K12: 0 | L12: =COUNTIFS(C:C,C12,E:E,1) -> 0 | M12: =_xlfn.MINIFS(D:D,C:C,C12,E:E,1) -> 0 | N12: =CHOOSE(L12+1,0,2/3,1,1) -> 0 | O12: =IF(L12>0,1,0) -> 0 | P12: =VLOOKUP(LEFT(C12,LEN(C12)-4)&"_"&D12&"_llm.dfy",T:U,2,0) -> 44 | Q12: =VLOOKUP(C12,Locs!A:C,3,0) -> 38 | R12: =VLOOKUP(C12,Locs!A:F,6,0) -> 0 | S12: =_xlfn.MINIFS(D:D,C:C,C12,E:E,1) -> 0 | T12: CombNK_4_llm.dfy | U12: 44
A13: 12 | B13: =C13&"-"&D13 -> CombNK.dfy-5 | C13: CombNK.dfy | D13: 5 | E13: 0 | F13: 10.552 | G13: 1.6973 | H13: 10.5437 | I13: -1 | J13: 0 | K13: 0 | L13: =COUNTIFS(C:C,C13,E:E,1) -> 0 | M13: =_xlfn.MINIFS(D:D,C:C,C13,E:E,1) -> 0 | N13: =CHOOSE(L13+1,0,2/3,1,1) -> 0 | O13: =IF(L13>0,1,0) -> 0 | P13: =VLOOKUP(LEFT(C13,LEN(C13)-4)&"_"&D13&"_llm.dfy",T:U,2,0) -> 44 | Q13: =VLOOKUP(C13,Locs!A:C,3,0) -> 38 | R13: =VLOOKUP(C13,Locs!A:F,6,0) -> 0 | S13: =_xlfn.MINIFS(D:D,C:C,C13,E:E,1) -> 0 | T13: CombNK_5_llm.dfy | U13: 44
... A331: 330 | B331: =C331&"-"&D331 -> task_id_809.dfy-5 | C331: task_id_809.dfy | D331: 5 | E331: 0 | F331: 5.505 | G331: 1.2432 | H331: 5.5013 | I331: 1 | J331: 0 | K331: 0 | L331: =COUNTIFS(C:C,C331,E:E,1) -> 0 | M331: =_xlfn.MINIFS(D:D,C:C,C331,E:E,1) -> 0 | N331: =CHOOSE(L331+1,0,2/3,1,1) -> 0 | O331: =IF(L331>0,1,0) -> 0 | P331: =VLOOKUP(LEFT(C331,LEN(C331)-4)&"_"&D331&"_llm.dfy",T:U,2,0) -> 27 | Q331: =VLOOKUP(C331,Locs!A:C,3,0) -> 29 | R331: =VLOOKUP(C331,Locs!A:F,6,0) -> 2 | S331: =_xlfn.MINIFS(D:D,C:C,C331,E:E,1) -> 0 | T331: task_id_8_1_llm.dfy | U331: 23
B332: =C332&"-"&D332 -> task_id_95.dfy-1 | C332: task_id_95.dfy | D332: 1 | E332: 0 | F332: 7.6421 | G332: 1.2456 | H332: 7.6205 | I332: 1 | J332: 0 | K332: 0 | L332: =COUNTIFS(C:C,C332,E:E,1) -> 0 | M332: =_xlfn.MINIFS(D:D,C:C,C332,E:E,1) -> 0 | N332: =CHOOSE(L332+1,0,2/3,1,1) -> 0 | O332: =IF(L332>0,1,0) -> 0 | P332: =VLOOKUP(LEFT(C332,LEN(C332)-4)&"_"&D332&"_llm.dfy",T:U,2,0) -> 26 | Q332: =VLOOKUP(C332,Locs!A:C,3,0) -> 32 | R332: =VLOOKUP(C332,Locs!A:F,6,0) -> 6 | S332: =_xlfn.MINIFS(D:D,C:C,C332,E:E,1) -> 0 | T332: task_id_95_1_llm.dfy | U332: 26
B333: =C333&"-"&D333 -> task_id_95.dfy-2 | C333: task_id_95.dfy | D333: 2 | E333: 0 | F333: 5.664 | G333: 1.3089 | H333: 5.6616 | I333: 1 | J333: 0 | K333: 0 | L333: =COUNTIFS(C:C,C333,E:E,1) -> 0 | M333: =_xlfn.MINIFS(D:D,C:C,C333,E:E,1) -> 0 | N333: =CHOOSE(L333+1,0,2/3,1,1) -> 0 | O333: =IF(L333>0,1,0) -> 0 | P333: =VLOOKUP(LEFT(C333,LEN(C333)-4)&"_"&D333&"_llm.dfy",T:U,2,0) -> 26 | Q333: =VLOOKUP(C333,Locs!A:C,3,0) -> 32 | R333: =VLOOKUP(C333,Locs!A:F,6,0) -> 6 | S333: =_xlfn.MINIFS(D:D,C:C,C333,E:E,1) -> 0 | T333: task_id_95_2_llm.dfy | U333: 26
B334: =C334&"-"&D334 -> task_id_95.dfy-3 | C334: task_id_95.dfy | D334: 3 | E334: 0 | F334: 5.7711 | G334: 1.2659 | H334: 5.7632 | I334: 1 | J334: 0 | K334: 0 | L334: =COUNTIFS(C:C,C334,E:E,1) -> 0 | M334: =_xlfn.MINIFS(D:D,C:C,C334,E:E,1) -> 0 | N334: =CHOOSE(L334+1,0,2/3,1,1) -> 0 | O334: =IF(L334>0,1,0) -> 0 | P334: =VLOOKUP(LEFT(C334,LEN(C334)-4)&"_"&D334&"_llm.dfy",T:U,2,0) -> 26 | Q334: =VLOOKUP(C334,Locs!A:C,3,0) -> 32 | R334: =VLOOKUP(C334,Locs!A:F,6,0) -> 6 | S334: =_xlfn.MINIFS(D:D,C:C,C334,E:E,1) -> 0 | T334: task_id_95_3_llm.dfy | U334: 26
B335: =C335&"-"&D335 -> task_id_95.dfy-4 | C335: task_id_95.dfy | D335: 4 | E335: 0 | F335: 5.8324 | G335: 1.2792 | H335: 5.8297 | I335: 1 | J335: 0 | K335: 0 | L335: =COUNTIFS(C:C,C335,E:E,1) -> 0 | M335: =_xlfn.MINIFS(D:D,C:C,C335,E:E,1) -> 0 | N335: =CHOOSE(L335+1,0,2/3,1,1) -> 0 | O335: =IF(L335>0,1,0) -> 0 | P335: =VLOOKUP(LEFT(C335,LEN(C335)-4)&"_"&D335&"_llm.dfy",T:U,2,0) -> 26 | Q335: =VLOOKUP(C335,Locs!A:C,3,0) -> 32 | R335: =VLOOKUP(C335,Locs!A:F,6,0) -> 6 | S335: =_xlfn.MINIFS(D:D,C:C,C335,E:E,1) -> 0 | T335: task_id_95_4_llm.dfy | U335: 26
B336: =C336&"-"&D336 -> task_id_95.dfy-5 | C336: task_id_95.dfy | D336: 5 | E336: 0 | F336: 5.783 | G336: 1.3344 | H336: 5.7751 | I336: 1 | J336: 0 | K336: 0 | L336: =COUNTIFS(C:C,C336,E:E,1) -> 0 | M336: =_xlfn.MINIFS(D:D,C:C,C336,E:E,1) -> 0 | N336: =CHOOSE(L336+1,0,2/3,1,1) -> 0 | O336: =IF(L336>0,1,0) -> 0 | P336: =VLOOKUP(LEFT(C336,LEN(C336)-4)&"_"&D336&"_llm.dfy",T:U,2,0) -> 26 | Q336: =VLOOKUP(C336,Locs!A:C,3,0) -> 32 | R336: =VLOOKUP(C336,Locs!A:F,6,0) -> 6 | S336: =_xlfn.MINIFS(D:D,C:C,C336,E:E,1) -> 0 | T336: task_id_95_5_llm.dfy | U336: 26

Sheet Results_GPT5.2Low
A1: Ordering | B1: Key | C1: Filename | D1: Attempt | E1: Success | F1: Time Gen | G1: Time Ver | H1: Time API Call | I1: Success Merged Original | J1: Success Raw | K1: Success Postprocessed | L1: C | M1: Attempts to Success | N1: pass@2 | O1: pass@3 | P1: LOC llm | Q1: LOC man | R1: Helpers + lemmas | S1: File | T1: LOC
A2: 1 | B2: =C2&"-"&D2 -> BinarySearch.dfy-1 | C2: BinarySearch.dfy | D2: 1 | E2: 1 | F2: 13.3909 | G2: 2.2487 | H2: 13.3728 | I2: 1 | J2: 1 | K2: 1 | L2: =COUNTIFS(C:C,C2,E:E,1) -> 3 | M2: =_xlfn.MINIFS(D:D,C:C,C2,E:E,1) -> 1 | N2: =CHOOSE(L2+1,0,2/3,1,1) -> 1 | O2: =IF(L2>0,1,0) -> 1 | P2: =VLOOKUP(LEFT(C2,LEN(C2)-4)&"_"&D2&"_llm.dfy",S:T,2,0) -> 44 | Q2: =VLOOKUP(C2,Locs!A:C,3,0) -> 38 | R2: =VLOOKUP(C2,Locs!A:F,6,0) -> 0 | S2: BinarySearch_1_llm.dfy | T2: 44
A3: 2 | B3: =C3&"-"&D3 -> BinarySearch.dfy-2 | C3: BinarySearch.dfy | D3: 2 | E3: 1 | F3: 8.5129 | G3: 2.2428 | H3: 8.5107 | I3: 1 | J3: 1 | K3: 1 | L3: =COUNTIFS(C:C,C3,E:E,1) -> 3 | M3: =_xlfn.MINIFS(D:D,C:C,C3,E:E,1) -> 1 | N3: =CHOOSE(L3+1,0,2/3,1,1) -> 1 | O3: =IF(L3>0,1,0) -> 1 | P3: =VLOOKUP(LEFT(C3,LEN(C3)-4)&"_"&D3&"_llm.dfy",S:T,2,0) -> 43 | Q3: =VLOOKUP(C3,Locs!A:C,3,0) -> 38 | R3: =VLOOKUP(C3,Locs!A:F,6,0) -> 0 | S3: BinarySearch_2_llm.dfy | T3: 43
A4: 3 | B4: =C4&"-"&D4 -> BinarySearch.dfy-3 | C4: BinarySearch.dfy | D4: 3 | E4: 1 | F4: 6.5352 | G4: 1.6851 | H4: 6.5329 | I4: 1 | J4: 1 | K4: 1 | L4: =COUNTIFS(C:C,C4,E:E,1) -> 3 | M4: =_xlfn.MINIFS(D:D,C:C,C4,E:E,1) -> 1 | N4: =CHOOSE(L4+1,0,2/3,1,1) -> 1 | O4: =IF(L4>0,1,0) -> 1 | P4: =VLOOKUP(LEFT(C4,LEN(C4)-4)&"_"&D4&"_llm.dfy",S:T,2,0) -> 46 | Q4: =VLOOKUP(C4,Locs!A:C,3,0) -> 38 | R4: =VLOOKUP(C4,Locs!A:F,6,0) -> 0 | S4: BinarySearch_3_llm.dfy | T4: 46
A5: 4 | B5: =C5&"-"&D5 -> BubbleSort.dfy-1 | C5: BubbleSort.dfy | D5: 1 | E5: 0 | F5: 96.9746 | G5: 3.6411 | H5: 96.9528 | I5: -1 | J5: 0 | K5: 0 | L5: =COUNTIFS(C:C,C5,E:E,1) -> 0 | M5: =_xlfn.MINIFS(D:D,C:C,C5,E:E,1) -> 0 | N5: =CHOOSE(L5+1,0,2/3,1,1) -> 0 | O5: =IF(L5>0,1,0) -> 0 | P5: =VLOOKUP(LEFT(C5,LEN(C5)-4)&"_"&D5&"_llm.dfy",S:T,2,0) -> 98 | Q5: =VLOOKUP(C5,Locs!A:C,3,0) -> 44 | R5: =VLOOKUP(C5,Locs!A:F,6,0) -> 1 | S5: BubbleSort_1_llm.dfy | T5: 98
A6: 5 | B6: =C6&"-"&D6 -> BubbleSort.dfy-2 | C6: BubbleSort.dfy | D6: 2 | E6: 0 | F6: 101.0192 | G6: 2.4527 | H6: 101.0111 | I6: -1 | J6: 0 | K6: 0 | L6: =COUNTIFS(C:C,C6,E:E,1) -> 0 | M6: =_xlfn.MINIFS(D:D,C:C,C6,E:E,1) -> 0 | N6: =CHOOSE(L6+1,0,2/3,1,1) -> 0 | O6: =IF(L6>0,1,0) -> 0 | P6: =VLOOKUP(LEFT(C6,LEN(C6)-4)&"_"&D6&"_llm.dfy",S:T,2,0) -> 146 | Q6: =VLOOKUP(C6,Locs!A:C,3,0) -> 44 | R6: =VLOOKUP(C6,Locs!A:F,6,0) -> 1 | S6: BubbleSort_2_llm.dfy | T6: 146
A7: 6 | B7: =C7&"-"&D7 -> BubbleSort.dfy-3 | C7: BubbleSort.dfy | D7: 3 | E7: 0 | F7: 95.0839 | G7: 2.7174 | H7: 95.0817 | I7: -1 | J7: 0 | K7: 0 | L7: =COUNTIFS(C:C,C7,E:E,1) -> 0 | M7: =_xlfn.MINIFS(D:D,C:C,C7,E:E,1) -> 0 | N7: =CHOOSE(L7+1,0,2/3,1,1) -> 0 | O7: =IF(L7>0,1,0) -> 0 | P7: =VLOOKUP(LEFT(C7,LEN(C7)-4)&"_"&D7&"_llm.dfy",S:T,2,0) -> 183 | Q7: =VLOOKUP(C7,Locs!A:C,3,0) -> 44 | R7: =VLOOKUP(C7,Locs!A:F,6,0) -> 1 | S7: BubbleSort_3_llm.dfy | T7: 183
A8: 7 | B8: =C8&"-"&D8 -> BubbleSort.dfy-4 | C8: BubbleSort.dfy | D8: 4 | E8: -1 | F8: 207.4272 | G8: 0.4236 | H8: 207.4196 | I8: -1 | J8: -1 | K8: -1 | L8: =COUNTIFS(C:C,C8,E:E,1) -> 0 | M8: =_xlfn.MINIFS(D:D,C:C,C8,E:E,1) -> 0 | N8: =CHOOSE(L8+1,0,2/3,1,1) -> 0 | O8: =IF(L8>0,1,0) -> 0 | P8: =VLOOKUP(LEFT(C8,LEN(C8)-4)&"_"&D8&"_llm.dfy",S:T,2,0) -> 192 | Q8: =VLOOKUP(C8,Locs!A:C,3,0) -> 44 | R8: =VLOOKUP(C8,Locs!A:F,6,0) -> 1 | S8: BubbleSort_4_llm.dfy | T8: 192
A9: 8 | B9: =C9&"-"&D9 -> BubbleSort.dfy-5 | C9: BubbleSort.dfy | D9: 5 | E9: 0 | F9: 117.9149 | G9: 2.3608 | H9: 117.9127 | I9: -1 | J9: 0 | K9: 0 | L9: =COUNTIFS(C:C,C9,E:E,1) -> 0 | M9: =_xlfn.MINIFS(D:D,C:C,C9,E:E,1) -> 0 | N9: =CHOOSE(L9+1,0,2/3,1,1) -> 0 | O9: =IF(L9>0,1,0) -> 0 | P9: =VLOOKUP(LEFT(C9,LEN(C9)-4)&"_"&D9&"_llm.dfy",S:T,2,0) -> 56 | Q9: =VLOOKUP(C9,Locs!A:C,3,0) -> 44 | R9: =VLOOKUP(C9,Locs!A:F,6,0) -> 1 | S9: BubbleSort_5_llm.dfy | T9: 56
A10: 9 | B10: =C10&"-"&D10 -> Catalan.dfy-1 | C10: Catalan.dfy | D10: 1 | E10: 1 | F10: 30.7428 | G10: 2.2412 | H10: 30.7227 | I10: 1 | J10: 1 | K10: 1 | L10: =COUNTIFS(C:C,C10,E:E,1) -> 2 | M10: =_xlfn.MINIFS(D:D,C:C,C10,E:E,1) -> 1 | N10: =CHOOSE(L10+1,0,2/3,1,1) -> 1 | O10: =IF(L10>0,1,0) -> 1 | P10: =VLOOKUP(LEFT(C10,LEN(C10)-4)&"_"&D10&"_llm.dfy",S:T,2,0) -> 56 | Q10: =VLOOKUP(C10,Locs!A:C,3,0) -> 28 | R10: =VLOOKUP(C10,Locs!A:F,6,0) -> 0 | S10: Catalan_1_llm.dfy | T10: 56
A11: 10 | B11: =C11&"-"&D11 -> Catalan.dfy-2 | C11: Catalan.dfy | D11: 2 | E11: 1 | F11: 32.4286 | G11: 1.3656 | H11: 32.4262 | I11: 1 | J11: 1 | K11: 1 | L11: =COUNTIFS(C:C,C11,E:E,1) -> 2 | M11: =_xlfn.MINIFS(D:D,C:C,C11,E:E,1) -> 1 | N11: =CHOOSE(L11+1,0,2/3,1,1) -> 1 | O11: =IF(L11>0,1,0) -> 1 | P11: =VLOOKUP(LEFT(C11,LEN(C11)-4)&"_"&D11&"_llm.dfy",S:T,2,0) -> 33 | Q11: =VLOOKUP(C11,Locs!A:C,3,0) -> 28 | R11: =VLOOKUP(C11,Locs!A:F,6,0) -> 0 | S11: Catalan_2_llm.dfy | T11: 33
A12: 11 | B12: =C12&"-"&D12 -> Catalan.dfy-3 | C12: Catalan.dfy | D12: 3 | E12: 0 | F12: 14.5678 | G12: 61.2425 | H12: 14.5579 | I12: -1 | J12: 0 | K12: 0 | L12: =COUNTIFS(C:C,C12,E:E,1) -> 2 | M12: =_xlfn.MINIFS(D:D,C:C,C12,E:E,1) -> 1 | N12: =CHOOSE(L12+1,0,2/3,1,1) -> 1 | O12: =IF(L12>0,1,0) -> 1 | P12: =VLOOKUP(LEFT(C12,LEN(C12)-4)&"_"&D12&"_llm.dfy",S:T,2,0) -> 32 | Q12: =VLOOKUP(C12,Locs!A:C,3,0) -> 28 | R12: =VLOOKUP(C12,Locs!A:F,6,0) -> 0 | S12: Catalan_3_llm.dfy | T12: 32
A13: 12 | B13: =C13&"-"&D13 -> CombNK.dfy-1 | C13: CombNK.dfy | D13: 1 | E13: 1 | F13: 26.414 | G13: 2.2477 | H13: 26.3899 | I13: 1 | J13: 1 | K13: 1 | L13: =COUNTIFS(C:C,C13,E:E,1) -> 2 | M13: =_xlfn.MINIFS(D:D,C:C,C13,E:E,1) -> 1 | N13: =CHOOSE(L13+1,0,2/3,1,1) -> 1 | O13: =IF(L13>0,1,0) -> 1 | P13: =VLOOKUP(LEFT(C13,LEN(C13)-4)&"_"&D13&"_llm.dfy",S:T,2,0) -> 48 | Q13: =VLOOKUP(C13,Locs!A:C,3,0) -> 38 | R13: =VLOOKUP(C13,Locs!A:F,6,0) -> 0 | S13: CombNK_1_llm.dfy | T13: 48
... A331: 330 | B331: =C331&"-"&D331 -> task_id_623.dfy-2 | C331: task_id_623.dfy | D331: 2 | E331: 1 | F331: 7.6334 | G331: 1.6663 | H331: 7.6315 | I331: 1 | J331: 1 | K331: 1 | L331: =COUNTIFS(C:C,C331,E:E,1) -> 2 | M331: =_xlfn.MINIFS(D:D,C:C,C331,E:E,1) -> 1 | N331: =CHOOSE(L331+1,0,2/3,1,1) -> 1 | O331: =IF(L331>0,1,0) -> 1 | P331: =VLOOKUP(LEFT(C331,LEN(C331)-4)&"_"&D331&"_llm.dfy",S:T,2,0) -> 25 | Q331: =VLOOKUP(C331,Locs!A:C,3,0) -> 25 | R331: =VLOOKUP(C331,Locs!A:F,6,0) -> 0 | S331: task_id_627_1_llm.dfy | T331: 35
B332: =C332&"-"&D332 -> task_id_623.dfy-3 | C332: task_id_623.dfy | D332: 3 | E332: -1 | F332: 22.3121 | G332: 0.2792 | H332: 22.3102 | I332: -1 | J332: -1 | K332: -1 | L332: =COUNTIFS(C:C,C332,E:E,1) -> 2 | M332: =_xlfn.MINIFS(D:D,C:C,C332,E:E,1) -> 1 | N332: =CHOOSE(L332+1,0,2/3,1,1) -> 1 | O332: =IF(L332>0,1,0) -> 1 | P332: =VLOOKUP(LEFT(C332,LEN(C332)-4)&"_"&D332&"_llm.dfy",S:T,2,0) -> 30 | Q332: =VLOOKUP(C332,Locs!A:C,3,0) -> 25 | R332: =VLOOKUP(C332,Locs!A:F,6,0) -> 0 | S332: task_id_627_2_llm.dfy | T332: 54
B333: =C333&"-"&D333 -> task_id_624.dfy-1 | C333: task_id_624.dfy | D333: 1 | E333: 1 | F333: 8.2973 | G333: 1.6714 | H333: 8.2756 | I333: 1 | J333: 1 | K333: 1 | L333: =COUNTIFS(C:C,C333,E:E,1) -> 3 | M333: =_xlfn.MINIFS(D:D,C:C,C333,E:E,1) -> 1 | N333: =CHOOSE(L333+1,0,2/3,1,1) -> 1 | O333: =IF(L333>0,1,0) -> 1 | P333: =VLOOKUP(LEFT(C333,LEN(C333)-4)&"_"&D333&"_llm.dfy",S:T,2,0) -> 22 | Q333: =VLOOKUP(C333,Locs!A:C,3,0) -> 22 | R333: =VLOOKUP(C333,Locs!A:F,6,0) -> 0 | S333: task_id_627_3_llm.dfy | T333: 30
B334: =C334&"-"&D334 -> task_id_624.dfy-2 | C334: task_id_624.dfy | D334: 2 | E334: 1 | F334: 11.404 | G334: 1.6544 | H334: 11.4025 | I334: 1 | J334: 1 | K334: 1 | L334: =COUNTIFS(C:C,C334,E:E,1) -> 3 | M334: =_xlfn.MINIFS(D:D,C:C,C334,E:E,1) -> 1 | N334: =CHOOSE(L334+1,0,2/3,1,1) -> 1 | O334: =IF(L334>0,1,0) -> 1 | P334: =VLOOKUP(LEFT(C334,LEN(C334)-4)&"_"&D334&"_llm.dfy",S:T,2,0) -> 22 | Q334: =VLOOKUP(C334,Locs!A:C,3,0) -> 22 | R334: =VLOOKUP(C334,Locs!A:F,6,0) -> 0 | S334: task_id_627_4_llm.dfy | T334: 40
B335: =C335&"-"&D335 -> task_id_624.dfy-3 | C335: task_id_624.dfy | D335: 3 | E335: 1 | F335: 10.3103 | G335: 1.6579 | H335: 10.3088 | I335: 1 | J335: 1 | K335: 1 | L335: =COUNTIFS(C:C,C335,E:E,1) -> 3 | M335: =_xlfn.MINIFS(D:D,C:C,C335,E:E,1) -> 1 | N335: =CHOOSE(L335+1,0,2/3,1,1) -> 1 | O335: =IF(L335>0,1,0) -> 1 | P335: =VLOOKUP(LEFT(C335,LEN(C335)-4)&"_"&D335&"_llm.dfy",S:T,2,0) -> 22 | Q335: =VLOOKUP(C335,Locs!A:C,3,0) -> 22 | R335: =VLOOKUP(C335,Locs!A:F,6,0) -> 0 | S335: task_id_627_5_llm.dfy | T335: 35
B336: =C336&"-"&D336 -> task_id_627.dfy-1 | C336: task_id_627.dfy | D336: 1 | E336: 0 | F336: 31.7552 | G336: 1.7271 | H336: 31.7437 | I336: -1 | J336: 0 | K336: 0 | L336: =COUNTIFS(C:C,C336,E:E,1) -> 0 | M336: =_xlfn.MINIFS(D:D,C:C,C336,E:E,1) -> 0 | N336: =CHOOSE(L336+1,0,2/3,1,1) -> 0 | O336: =IF(L336>0,1,0) -> 0 | P336: =VLOOKUP(LEFT(C336,LEN(C336)-4)&"_"&D336&"_llm.dfy",S:T,2,0) -> 35 | Q336: =VLOOKUP(C336,Locs!A:C,3,0) -> 36 | R336: =VLOOKUP(C336,Locs!A:F,6,0) -> 6 | S336: task_id_629_1_llm.dfy | T336: 42
B337: =C337&"-"&D337 -> task_id_627.dfy-2 | C337: task_id_627.dfy | D337: 2 | E337: 0 | F337: 45.4918 | G337: 1.7295 | H337: 45.4899 | I337: -1 | J337: 0 | K337: 0 | L337: =COUNTIFS(C:C,C337,E:E,1) -> 0 | M337: =_xlfn.MINIFS(D:D,C:C,C337,E:E,1) -> 0 | N337: =CHOOSE(L337+1,0,2/3,1,1) -> 0 | O337: =IF(L337>0,1,0) -> 0 | P337: =VLOOKUP(LEFT(C337,LEN(C337)-4)&"_"&D337&"_llm.dfy",S:T,2,0) -> 54 | Q337: =VLOOKUP(C337,Locs!A:C,3,0) -> 36 | R337: =VLOOKUP(C337,Locs!A:F,6,0) -> 6 | S337: task_id_629_2_llm.dfy | T337: 53
